Workbook

Sheet ปกรายงาน
A3: สรุปยอดขาย
A4: เดือน พฤษภาคม 2569
A11: บริษัทเบสท์เวิลด์ อินเตอร์พลาส จำกัด
A12: BEST WORLD INTERPLAS CO.,LTD.

Sheet กราฟยอดขาย 69
F8: ปี57
F9: ปี68 | G9: ปี69
E10: ม.ค. | F10: =+D60 -> 489981.28 | G10: =+H60 -> 558941.06
E11: ก.พ. | F11: =+D61 -> 538468.56 | G11: =+H61 -> 561976.65
E12: มี.ค. | F12: =+D62 -> 656094.53 | G12: =+H62 -> 653338.81
E13: เม.ย. | F13: =+D63 -> 571816.38 | G13: =+H63 -> 720476.77
E14: พ.ค. | F14: =+D64 -> 609063.32 | G14: =+H64 -> 645959.6
E15: มิ.ย. | F15: =+D65 -> 518142.92 | G15: =+H65 -> 0
E16: ก.ค. | F16: =+D66 -> 598462.12 | G16: =+H66 -> 0
E17: ส.ค. | F17: =+D67 -> 537848.67 | G17: =+H67 -> 0
E18: ก.ย. | F18: =+D68 -> 569528.1 | G18: =+H68 -> 0
E19: ต.ค. | F19: =+D69 -> 516554.96 | G19: =+H69 -> 0
E20: พ.ย. | F20: =+D70 -> 508400.06 | G20: =+H70 -> 0
E21: ธ.ค. | F21: =+D71 -> 595252.27 | G21: =+H71 -> 0
A23: :กราฟแสดงตารางเปรียบเทียบยอดขายระหว่าง เดือน ม.ค.- ธ.ค. ปี 68-69
F38: ปี68 | G38: ปี69
E39: ม.ค. | F39: =+E60 -> 34735765 | G39: =+I60 -> 32494837
E40: ก.พ. | F40: =+E61 -> 36840992 | G40: =+I61 -> 32378293
E41: มี.ค. | F41: =+E62 -> 45332205 | G41: =+I62 -> 38381393
E42: เม.ย. | F42: =+E63 -> 38101958 | G42: =+I63 -> 53379281
E43: พ.ค. | F43: =+E64 -> 40498296 | G43: =+I64 -> 59376880
E44: มิ.ย. | F44: =+E65 -> 35323734 | G44: =+I65 -> 0
E45: ก.ค. | F45: =+E66 -> 36452704 | G45: =+I66 -> 0
E46: ส.ค. | F46: =+E67 -> 31884198 | G46: =+I67 -> 0
E47: ก.ย. | F47: =+E68 -> 33750598 | G47: =+I68 -> 0
E48: ต.ค. | F48: =+E69 -> 29949967 | G48: =+I69 -> 0
E49: พ.ย. | F49: =+E70 -> 30435492 | G49: =+I70 -> 0
E50: ธ.ค. | F50: =+E71 -> 35744232 | G50: =+I71 -> 0
A51: :กราฟแสดงตารางเปรียบเทียบมูลค่าขายระหว่าง เดือน ม.ค.- ธ.ค. ปี ปี 68-69
C59: เดือน | D59: ยอดขาย(กก.) | E59: มูลค่าขาย(บาท) | G59: เดือน | H59: ยอดขาย(กก.) | I59: มูลค่าขาย(บาท)
C60: ม.ค.68 | D60: 489981.28 | E60: 34735765 | G60: ม.ค.69 | H60: 558941.06 | I60: 32494837
C61: ก.พ.68 | D61: 538468.56 | E61: 36840992 | G61: ก.พ.69 | H61: 561976.65 | I61: 32378293
C62: มี.ค.68 | D62: 656094.53 | E62: 45332205 | G62: มี.ค.69 | H62: 653338.81 | I62: 38381393
C63: เม.ย.68 | D63: 571816.38 | E63: 38101958 | G63: เม.ย.69 | H63: 720476.77 | I63: 53379281
C64: พ.ค.68 | D64: 609063.32 | E64: 40498296 | G64: พ.ค.69 | H64: 645959.6 | I64: 59376880
C65: มิ.ย.68 | D65: 518142.92 | E65: 35323734 | G65: มิ.ย.69
C66: ก.ค.68 | D66: 598462.12 | E66: 36452704 | G66: ก.ค.69
C67: ส.ค.68 | D67: 537848.67 | E67: 31884198 | G67: ส.ค.69
C68: ก.ย.68 | D68: 569528.1 | E68: 33750598 | G68: ก.ย.69
C69: ต.ค.68 | D69: 516554.96 | E69: 29949967 | G69: ต.ค.69
...

Sheet มกราคม
A1: รายการขายสินค้า BWP เป็นผู้ผลิต
A2: บจก.ที.ซี.ฟาร์มาซูติคอล อุตสาหกรรม
A3: วันที่ | B3: ขนาด | C3: จำนวน(กก.) | D3: ราคา | E3: มูลค่าก่อน VAT | F3: VAT | G3: มูลค่ารวม VAT
A4: 06/01/69 | B4: 31 cm. x 50 mc. | C4: 489.1 | D4: 52 | E4: =+C4*D4 -> 25433.2 | F4: =+E4*7% -> 1780.324 | G4: =+E4+F4 -> 27213.524 | I4: 6901026 | J4: 6901352 | K4: บิลBSS
A5: 31/01/69 | B5: 31 cm. x 50 mc. | C5: 469.3 | D5: 52 | E5: =+C5*D5 -> 24403.6 | F5: =+E5*7% -> 1708.252 | G5: =+E5+F5 -> 26111.852 | I5: 6901353
A6: 05/01/69 | B6: 49 cm. x 45mc.(สูตร 1) | C6: 486.85 | D6: 52 | E6: =+C6*D6 -> 25316.2 | F6: =+E6*7% -> 1772.134 | G6: =+E6+F6 -> 27088.334 | I6: 6901003
A7: 10/01/69 | B7: 49 cm. x 45mc.(สูตร 1) | C7: 966.9 | D7: 52 | E7: =+C7*D7 -> 50278.8 | F7: =+E7*7% -> 3519.516 | G7: =+E7+F7 -> 53798.316 | I7: 6901103
A8: 06/01/69 | B8: 54 cm. x 45 mc. | C8: 4785.41 | D8: 52 | E8: =+C8*D8 -> 248841.32 | F8: =+E8*7% -> 17418.892 | G8: =+E8+F8 -> 266260.21 | I8: 6901029
A9: 05/01/69 | B9: 54 cm. x 45 mc. | C9: 4789.34 | D9: 52 | E9: =+C9*D9 -> 249045.68 | F9: =+E9*7% -> 17433.198 | G9: =+E9+F9 -> 266478.88 | I9: 6901002
A10: 08/01/68 | B10: 54 cm. x 45 mc. | C10: 4793.09 | D10: 52 | E10: =+C10*D10 -> 249240.68 | F10: =+E10*7% -> 17446.848 | G10: =+E10+F10 -> 266687.53 | I10: 6901064
A11: 10/01/69 | B11: 54 cm. x 45 mc. | C11: 4791.25 | D11: 52 | E11: =+C11*D11 -> 249145 | F11: =+E11*7% -> 17440.15 | G11: =+E11+F11 -> 266585.15 | I11: 6901101
A12: 13/01/69 | B12: 54 cm. x 45 mc. | C12: 4781.03 | D12: 52 | E12: =+C12*D12 -> 248613.56 | F12: =+E12*7% -> 17402.949 | G12: =+E12+F12 -> 266016.51 | I12: 6901133
A13: 14/01/69 | B13: 54 cm. x 45 mc. | C13: 4779.47 | D13: 52 | E13: =+C13*D13 -> 248532.44 | F13: =+E13*7% -> 17397.271 | G13: =+E13+F13 -> 265929.71 | I13: 6901144
A14: 16/01/69 | B14: 54 cm. x 45 mc. | C14: 4792.67 | D14: 52 | E14: =+C14*D14 -> 249218.84 | F14: =+E14*7% -> 17445.319 | G14: =+E14+F14 -> 266664.16 | I14: 6901184
A15: 17/01/69 | B15: 54 cm. x 45 mc. | C15: 4787.13 | D15: 52 | E15: =+C15*D15 -> 248930.76 | F15: =+E15*7% -> 17425.153 | G15: =+E15+F15 -> 266355.91 | I15: 6901195
A16: 22/01/69 | B16: 54 cm. x 45 mc. | C16: 4779.17 | D16: 52 | E16: =+C16*D16 -> 248516.84 | F16: =+E16*7% -> 17396.179 | G16: =+E16+F16 -> 265913.02 | I16: 6901237
... A54: 13/01/69 | B54: 54 cm. x 45 mc.ชาขาวเพียวริคุ (สตรอเบอร์รี่) 1x6/350มล. | C54: 478.58 | D54: 68 | E54: =+C54*D54 -> 32543.44 | F54: =+E54*7% -> 2278.0408 | G54: =+E54+F54 -> 34821.481 | I54: 6901138
B55: รวม | C55: =SUM(C4:C54) -> 106756.59 | E55: =SUM(E4:E54) -> 6328182.7 | F55: =SUM(F4:F54) -> 442972.79 | G55: =SUM(G4:G54) -> 6771155.5
A57: บจก.ไทยน้ำทิพย์ (คลอง13)
A58: วันที่ | B58: ขนาด | C58: จำนวน(กก.) | D58: ราคา | E58: มูลค่าก่อน VAT | F58: VAT | G58: มูลค่ารวม VAT
A59: 29/01/69 | B59: 36cm. x 50mc. | C59: 544.15 | D59: 50.12 | E59: =+C59*D59 -> 27272.798 | F59: =+E59*7% -> 1909.0959 | G59: =+E59+F59 -> 29181.894 | I59: 6901320
A60: 30/01/69 | B60: 36cm. x 50mc. | C60: 264.85 | D60: 50.12 | E60: =+C60*D60 -> 13274.282 | F60: =+E60*7% -> 929.19974 | G60: =+E60+F60 -> 14203.482 | I60: 6901339
A61: 10/01/69 | B61: 38cm. x 55mc. | C61: 1964.6 | D61: 50.12 | E61: =+C61*D61 -> 98465.752 | F61: =+E61*7% -> 6892.6026 | G61: =+E61+F61 -> 105358.35 | I61: 6901104
A62: 29/01/69 | B62: 50 cm. x 70mc. | C62: 1566.7 | D62: 50.12 | E62: =+C62*D62 -> 78523.004 | F62: =+E62*7% -> 5496.6103 | G62: =+E62+F62 -> 84019.614 | I62: 6901319
A63: 28/01/69 | B63: 50 cm. x 75mc. | C63: 2576.9 | D63: 50.12 | E63: =+C63*D63 -> 129154.23 | F63: =+E63*7% -> 9040.796 | G63: =+E63+F63 -> 138195.02 | I63: 6901314
A64: 13/01/69 | B64: 50 cm. x 75mc. | C64: 4195.2 | D64: 50.12 | E64: =+C64*D64 -> 210263.42 | F64: =+E64*7% -> 14718.44 | G64: =+E64+F64 -> 224981.86 | I64: 6901129
A65: 17/01/69 | B65: 50 cm. x 80mc. | C65: 3039.5 | D65: 50.12 | E65: =+C65*D65 -> 152339.74 | F65: =+E65*7% -> 10663.782 | G65: =+E65+F65 -> 163003.52 | I65: 6901196
A66: 22/01/69 | B66: 50 cm. x 80mc. | C66: 2592.25 | D66: 50.12 | E66: =+C66*D66 -> 129923.57 | F66: =+E66*7% -> 9094.6499 | G66: =+E66+F66 -> 139018.22 | I66: 6901243
A67: 14/01/69 | B67: 76 cm. X 55 mc. | C67: 2572.8 | D67: 50.12 | E67: =+C67*D67 -> 128948.74 | F67: =+E67*7% -> 9026.4115 | G67: =+E67+F67 -> 137975.15 | I67: 6901143
A68: 20/01/69 | B68: 76 cm. X 55 mc. | C68: 2571.2 | D68: 50.12 | E68: =+C68*D68 -> 128868.54 | F68: =+E68*7% -> 9020.7981 | G68: =+E68+F68 -> 137889.34 | I68: 6901212
A69: 05/01/69 | B69: 84 cm. X 55 mc. | C69: 5111.55 | D69: 50.12 | E69: =+C69*D69 -> 256190.89 | F69: =+E69*7% -> 17933.362 | G69: =+E69+F69 -> 274124.25 | I69: 6901038
A70: 05/01/69 | B70: 84 cm. X 55 mc. | C70: 5122.5 | D70: 50.12 | E70: =+C70*D70 -> 256739.7 | F70: =+E70*7% -> 17971.779 | G70: =+E70+F70 -> 274711.48 | I70: 6901001
... A75: 23/01/69 | B75: 84 cm. X 55 mc. | C75: 5118.9 | D75: 50.12 | E75: =+C75*D75 -> 256559.27 | F75: =+E75*7% -> 17959.149 | G75: =+E75+F75 -> 274518.42 | I75: 6901247
B76: รวม | C76: =SUM(C59:C75) -> 55934.15 | E76: =SUM(E59:E75) -> 2803419.6 | F76: =SUM(F59:F75) -> 196239.37 | G76: =SUM(G59:G75) -> 2999659
A78: บจก.ไทยน้ำทิพย์ (โคราช)
A79: วันที่ | B79: ขนาด | C79: จำนวน(กก.) | D79: ราคา | E79: มูลค่าก่อน VAT | F79: VAT | G79: มูลค่ารวม VAT
A80: 07/01/69 | B80: 50cm. x 75mc. | C80: 3049.8 | D80: 50.12 | E80: =+C80*D80 -> 152855.98 | F80: =+E80*7% -> 10699.918 | G80: =+E80+F80 -> 163555.89 | I80: 6901049
A81: 28/01/69 | B81: 50cm. x 75mc. | C81: 3082.25 | D81: 50.12 | E81: =+C81*D81 -> 154482.37 | F81: =+E81*7% -> 10813.766 | G81: =+E81+F81 -> 165296.14 | I81: 6901312
A82: 08/01/69 | B82: 50 cm. x 80mc. | C82: 6142.9 | D82: 50.12 | E82: =+C82*D82 -> 307882.15 | F82: =+E82*7% -> 21551.75 | G82: =+E82+F82 -> 329433.9 | I82: 6901062
A83: 14/01/69 | B83: 50cm. x 80mc. | C83: 6088.9 | D83: 50.12 | E83: =+C83*D83 -> 305175.67 | F83: =+E83*7% -> 21362.297 | G83: =+E83+F83 -> 326537.96 | I83: 6901142
...

Sheet ยอดขายรวม มค.
A1: รายการขายสินค้าประจำเดือน มกราคม 2569 | L1: งานพิมพ์ประจำเดือน มกราคม 2569 | U1: Supplier งานพิมพ์ประจำเดือน มกราคม 2569 | AA1: ถุงคลุม/ชีท ประจำเดือน มกราคม 2569
A2: ลำดับที่ | B2: ลูกค้า | C2: ม้วนใส (กก.) | D2: ม้วนพิมพ์ (กก.) | E2: ถุงคลุม/ชีท (กก.) | F2: ฟิล์มยืด(กก.) | G2: ถุงหลอด(กก.) | H2: รวม (กก.) | I2: หมายเหตุ | L2: ลำดับที่ | M2: ลูกค้า | N2: 1สี (กก.) | O2: 2สี (กก.) | P2: 3สี (กก.) | Q2: 4สี (กก.) | R2: 8สี (กก.) | S2: รวม (กก.) | U2: ลำดับที่ | V2: ลูกค้า | W2: BWP | X2: ว่องไท | Y2: รวม (กก.) | AA2: ลำดับที่ | AB2: ลูกค้า | AC2: ผลิตเอง (กก.) | AD2: จำนวน( ใบ.) | AE2: จ้างภายนอก (กก.) | AF2: รวม (กก.)
A3: 1 | B3: ไทยน้ำทิพย์ | C3: 151633.46 | D3: 0 | E3: 0 | F3: 0 | G3: 0 | H3: =+C3+D3+E3+F3+G3 -> 151633.46 | J3: =+H3*100/H48 -> 27.128703 | L3: 1 | M3: ที.ซีฟาร์มาฯ | N3: 0 | O3: 37324.89 | P3: 0 | Q3: 0 | R3: 0 | S3: =+N3+O3+P3+Q3+R3 -> 37324.89 | T3: =+S3*100/S12 -> 34.483514 | U3: 1 | V3: ที.ซีฟาร์มาฯ | W3: 37324.89 | X3: 0 | Y3: =+W3+X3 -> 37324.89 | AA3: 1 | AB3: สยามอุตสาหกรรมวัสดุทนไฟ | AC3: 5361.992 | AD3: 17300 | AE3: 0 | AF3: =+AC3+AE3 -> 5361.992
A4: 2 | B4: ที.ซีฟาร์มาฯ | C4: 69431.7 | D4: 37324.89 | E4: 0 | F4: 0 | G4: 0 | H4: =+C4+D4+E4+F4+G4 -> 106756.59 | J4: =+H4*100/H48 -> 19.099794 | L4: 2 | M4: กรีนสปอต | N4: 395.45 | O4: 29456.06 | P4: 0 | Q4: 0 | R4: 0 | S4: =+N4+O4+P4+Q4+R4 -> 29851.51 | T4: =+S4*100/S12 -> 27.579049 | U4: 2 | V4: กรีนสปอต | W4: 24096.25 | X4: 5755.26 | Y4: =+W4+X4 -> 29851.51 | AA4: 2 | AB4: เอ็น พลัส ชัพพลาย | AC4: 4432 | AD4: 4000 | AE4: 0 | AF4: =+AC4+AE4 -> 4432
A5: 3 | B5: หาดทิพย์ | C5: 93627.69 | D5: 0 | E5: 0 | F5: 0 | G5: 0 | H5: =+C5+D5+E5+F5+G5 -> 93627.69 | J5: =+H5*100/H48 -> 16.750906 | L5: 3 | M5: ฟรีสแลนด์คัมพิน่า | N5: 0 | O5: 16057.48 | P5: 0 | Q5: 0 | R5: 0 | S5: =+N5+O5+P5+Q5+R5 -> 16057.48 | T5: =+S5*100/S12 -> 14.835096 | U5: 3 | V5: ฟรีสแลนด์คัมพิน่า | W5: 16057.48 | X5: 0 | Y5: =+W5+X5 -> 16057.48 | AA5: 3 | AB5: เอสซีจี เซรามิกส์ | AC5: 364.8 | AD5: 1000 | AE5: 0 | AF5: =+AC5+AE5 -> 364.8
A6: 4 | B6: โอสถสภา | C6: 42651.8 | D6: 0 | E6: 0 | F6: 0 | G6: 0 | H6: =+C6+D6+E6+F6+G6 -> 42651.8 | J6: =+H6*100/H48 -> 7.6308225 | L6: 4 | M6: โตโยไซกัน | N6: 0 | O6: 14250.43 | P6: 0 | Q6: 0 | R6: 36.4 | S6: =+N6+O6+P6+Q6+R6 -> 14286.83 | T6: =+S6*100/S12 -> 13.199238 | U6: 4 | V6: โตโยไซกัน | W6: 14286.83 | X6: 0 | Y6: =+W6+X6 -> 14286.83 | AA6: 4 | AB6: สยามกลาสอยุธยา | AC6: 251.15 | AD6: 500 | AE6: 0 | AF6: =+AC6+AE6 -> 251.15
A7: 5 | B7: กรีนสปอต | C7: 5456.24 | D7: 29851.51 | E7: 0 | F7: 795.6 | G7: 0 | H7: =+C7+D7+E7+F7+G7 -> 36103.35 | J7: =+H7*100/H48 -> 6.459241 | L7: 5 | M7: สหกรณ์โคนมหนองโพ | N7: 0 | O7: 966.5 | P7: 0 | Q7: 0 | R7: 0 | S7: =+N7+O7+P7+Q7+R7 -> 966.5 | T7: =+S7*100/S12 -> 0.8929247 | U7: 5 | V7: สหกรณ์โคนมหนองโพ | W7: 966.5 | X7: 0 | Y7: =+W7+X7 -> 966.5 | AB7: ผลรวม | AC7: =SUM(AC3:AC6) -> 10409.942 | AD7: =SUM(AD3:AD6) -> 22800 | AE7: =SUM(AE3:AE6) -> 0 | AF7: =SUM(AF3:AF6) -> 10409.942
A8: 6 | B8: ฟรีสแลนด์คัมพิน่า | C8: 0 | D8: 16057.48 | E8: 0 | F8: 0 | G8: 0 | H8: =+C8+D8+E8+F8+G8 -> 16057.48 | J8: =+H8*100/H48 -> 2.8728396 | L8: 6 | M8: แอดวานซ์ โนเลดจ์ เซอร์วิสเซส | N8: 0 | O8: 4941.7 | P8: 0 | Q8: 0 | R8: 0 | S8: =+N8+O8+P8+Q8+R8 -> 4941.7 | T8: =+S8*100/S12 -> 4.5655106 | U8: 6 | V8: แอดวานซ์ โนเลดจ์ เซอร์วิสเซส | W8: 4941.7 | X8: 0 | Y8: =+W8+X8 -> 4941.7
A9: 7 | B9: ทิพย์นที (2005) | C9: 14973.45 | D9: 0 | E9: 0 | F9: 0 | G9: 0 | H9: =+C9+D9+E9+F9+G9 -> 14973.45 | J9: =+H9*100/H48 -> 2.6788961 | L9: 7 | M9: สยามไฟเบอร์ซีเมนต์กรุ๊ป | N9: 0 | O9: 3586.2 | P9: 0 | Q9: 0 | R9: 0 | S9: =+N9+O9+P9+Q9+R9 -> 3586.2 | T9: =+S9*100/S12 -> 3.3131987 | U9: 7 | V9: สยามไฟเบอร์ซีเมนต์กรุ๊ป | W9: 3586.2 | X9: 0 | Y9: =+W9+X9 -> 3586.2
A10: 8 | B10: โตโยไซกัน | C10: 72.25 | D10: 14286.83 | E10: 0 | F10: 0 | G10: 0 | H10: =+C10+D10+E10+F10+G10 -> 14359.08 | J10: =+H10*100/H48 -> 2.5689793 | L10: 8 | M10: ทิปโก้ | N10: 198.2 | O10: 0 | P10: 0 | Q10: 0 | R10: 0 | S10: =+N10+O10+P10+Q10+R10 -> 198.2 | T10: =+S10*100/S12 -> 0.18311193 | U10: 8 | V10: ทิปโก้ | W10: 198.2 | X10: 0 | Y10: =+W10+X10 -> 198.2
A11: 9 | B11: เสริมสุข | C11: 12205.4 | D11: 0 | E11: 0 | F11: 0 | G11: 0 | H11: =+C11+D11+E11+F11+G11 -> 12205.4 | J11: =+H11*100/H48 -> 2.1836649 | L11: 10 | M11: ยูนิ-เพรสซิเดนท์ | N11: 0 | O11: 1026.5 | P11: 0 | Q11: 0 | R11: 0 | S11: =+N11+O11+P11+Q11+R11 -> 1026.5 | T11: =+S11*100/S12 -> 0.94835717 | U11: 10 | V11: ยูนิ-เพรสซิเดนท์ | W11: 1026.5 | X11: 0 | Y11: =+W11+X11 -> 1026.5
A12: 10 | B12: สหกรณ์โคนมหนองโพ | C12: 6994.6 | D12: 966.5 | E12: 0 | F12: 0 | G12: 0 | H12: =+C12+D12+E12+F12+G12 -> 7961.1 | J12: =+H12*100/H48 -> 1.4243183 | M12: ผลรวม | N12: =SUM(N3:N11) -> 593.65 | O12: =SUM(O3:O11) -> 107609.76 | P12: =SUM(P3:P11) -> 0 | Q12: =SUM(Q3:Q11) -> 0 | R12: =SUM(R3:R11) -> 36.4 | S12: =SUM(S3:S11) -> 108239.81 | V12: ผลรวม | W12: =SUM(W3:W11) -> 102484.55 | X12: =SUM(X3:X11) -> 5755.26 | Y12: =SUM(Y3:Y11) -> 108239.81
A13: 11 | B13: กรีนสวิลล์ | C13: 7209.95 | D13: 0 | E13: 0 | F13: 0 | G13: 0 | H13: =+C13+D13+E13+F13+G13 -> 7209.95
A14: 12 | B14: เอ็มเอ็มพี คอร์ปอเรชั่น | C14: 6263.1 | D14: 0 | E14: 0 | F14: 0 | G14: 0 | H14: =+C14+D14+E14+F14+G14 -> 6263.1 | N14: =+N12*100/S12 -> 0.5484581 | O14: =+O12*100/S12 -> 99.417913 | P14: =+P12*100/S12 -> 0 | Q14: =+Q12*100/S12 -> 0 | R14: =+R12*100/S12 -> 0.033629032 | W14: =+W12*100/Y12 -> 94.682862 | X14: =+X12*100/Y12 -> 5.3171379
A15: 13 | B15: สยามอุตสาหกรรมวัสดุทนไฟ | C15: 0 | D15: 0 | E15: 5361.99 | F15: 0 | G15: 0 | H15: =+C15+D15+E15+F15+G15 -> 5361.99
A16: 14 | B16: แอดวานซ์ โนเลดจ์ เซอร์วิสเซส | C16: 0 | D16: 4941.7 | E16: 0 | F16: 0 | G16: 0 | H16: =+C16+D16+E16+F16+G16 -> 4941.7
A17: 15 | B17: เอ็น พลัส ชัพพลาย | C17: 0 | D17: 0 | E17: 4432 | F17: 0 | G17: 0 | H17: =+C17+D17+E17+F17+G17 -> 4432
A18: 16 | B18: ขายยาเพ็ญภาค | C18: 3929.85 | D18: 0 | E18: 0 | F18: 0 | G18: 0 | H18: =+C18+D18+E18+F18+G18 -> 3929.85
A19: 17 | B19: สยามไฟเบอร์ซีเมนต์กรุ๊ป | C19: 0 | D19: 3586.2 | E19: 0 | F19: 0 | G19: 0 | H19: =+C19+D19+E19+F19+G19 -> 3586.2
A20: 18 | B20: เซเว่นสตาร์ | C20: 3459.3 | D20: 0 | E20: 0 | F20: 0 | G20: 0 | H20: =+C20+D20+E20+F20+G20 -> 3459.3
A21: 19 | B21: เถิงธงพานิชย์ | C21: 2747.6 | D21: 0 | E21: 0 | F21: 0 | G21: 0 | H21: =+C21+D21+E21+F21+G21 -> 2747.6
A22: 20 | B22: ซันสวีท | C22: 2566.65 | D22: 0 | E22: 0 | F22: 0 | G22: 0 | H22: =+C22+D22+E22+F22+G22 -> 2566.65
A23: 21 | B23: พลอยพรรณราย อินดัสตรี | C23: 2560.55 | D23: 0 | E23: 0 | F23: 0 | G23: 0 | H23: =+C23+D23+E23+F23+G23 -> 2560.55
A24: 22 | B24: สุรใจฟู้ดส์อินดัสทรี | C24: 2378.5 | D24: 0 | E24: 0 | F24: 0 | G24: 0 | H24: =+C24+D24+E24+F24+G24 -> 2378.5
A25: 23 | B25: ฐิติภัณฑ์ อินเตอร์พลัส | C25: 1972 | D25: 0 | E25: 0 | F25: 0 | G25: 0 | H25: =+C25+D25+E25+F25+G25 -> 1972
A26: 24 | B26: เพชรพาณิชย์ เบฟเวอเรจ | C26: 1951.65 | D26: 0 | E26: 0 | F26: 0 | G26: 0 | H26: =+C26+D26+E26+F26+G26 -> 1951.65
... A47: 45 | B47: แอโร เซลล์ แอนด์ เนจิเนียริ่ง | C47: 0 | D47: 0 | E47: 0 | F47: 24.84 | G47: 0 | H47: =+C47+D47+E47+F47+G47 -> 24.84
A48: ผลรวม | C48: =SUM(C3:C47) -> 438464.53 | D48: =SUM(D3:D47) -> 108239.81 | E48: =SUM(E3:E47) -> 10409.94 | F48: =SUM(F3:F47) -> 1826.78 | G48: =SUM(G3:G47) -> 0 | H48: =SUM(H3:H47) -> 558941.06
C50: =+C48*100/H48 -> 78.445575 | D50: =+D48*100/H48 -> 19.365156 | E50: =+E48*100/H48 -> 1.8624397 | F50: =+F48*100/H48 -> 0.32682874 | G50: =+G48*100/H48 -> 0
A56: สรุปยอดขายแยกประเภทสินค้าประจำปี 2568 | L56: สรุปงานพิมพ์ ประจำปี 2568 | U56: สรุป Supplier งานพิมพ์ ประจำปี 2568 | AA56: ถุงคลุม/ชีท ประจำปี 2568
A57: ลำดับที่ | B57: เดือน | C57: ม้วนใส (กก.) | D57: ม้วนพิมพ์ (กก.) | E57: ถุงคลุม/ชีท (กก.) | F57: ฟิล์มยืด(กก,) | G57: ถุงหลอด(กก.) | H57: รวม (กก.) | I57: หมายเหตุ | L57: ลำดับที่ | M57: เดือน | N57: 1สี (กก.) | O57: 2สี (กก.) | P57: 3สี (กก.) | Q57: 4สี (กก.) | R57: 8สี (กก.) | S57: รวม (กก.) | U57: ลำดับที่ | V57: เดือน | W57: BWP | X57: ว่องไท | Y57: รวม (กก.) | AA57: ลำดับที่ | AB57: ลูกค้า | AC57: ผลิตเอง (กก.) | AD57: จำนวน( ใบ.) | AE57: จ้างภายนอก (กก.) | AF57: รวม (กก.)
A58: 1 | B58: มกราคม | C58: 438464.53 | D58: 108239.81 | E58: 10409.94 | F58: 1826.78 | G58: 0 | H58: =+C58+D58+E58+F58+G58 -> 558941.06 | L58: 1 | M58: มกราคม | N58: 593.65 | O58: 107609.76 | P58: 0 | Q58: 0 | R58: 36.4 | S58: =+N58+O58 -> 108203.41 | U58: 1 | V58: มกราคม | W58: 102484.55 | X58: 5755.26 | Y58: =+W58+X58 -> 108239.81 | AA58: 1 | AB58: มกราคม | AC58: 10409.942 | AD58: 22800 | AE58: 0 | AF58: =+AC58+AE58 -> 10409.942
A59: 2 | B59: กุมภาพันธ์ | H59: =+C59+D59+E59+F59+G59 -> 0 | L59: 2 | M59: กุมภาพันธ์ | S59: =+N59+O59 -> 0 | U59: 2 | V59: กุมภาพันธ์ | Y59: =+W59+X59 -> 0 | AA59: 2 | AB59: กุมภาพันธ์ | AC59: 0 | AD59: 0 | AE59: =AE9 -> 0 | AF59: =+AC59+AE59 -> 0
A60: 3 | B60: มีนาคม | H60: =+C60+D60+E60+F60+G60 -> 0 | L60: 3 | M60: มีนาคม | S60: =+N60+O60 -> 0 | U60: 3 | V60: มีนาคม | Y60: =+W60+X60 -> 0 | AA60: 3 | AB60: มีนาคม | AC60: 0 | AD60: 0 | AE60: =AE10 -> 0 | AF60: =+AC60+AE60 -> 0
A61: 4 | B61: เมษายน | H61: =+C61+D61+E61+F61+G61 -> 0 | L61: 4 | M61: เมษายน | S61: =+N61+O61 -> 0 | U61: 4 | V61: เมษายน | Y61: =+W61+X61 -> 0 | AA61: 4 | AB61: เมษายน | AC61: 0 | AD61: 0 | AE61: =AE11 -> 0 | AF61: =+AC61+AE61 -> 0
A62: 5 | B62: พฤษภาคม | H62: =+C62+D62+E62+F62+G62 -> 0 | L62: 5 | M62: พฤษภาคม | S62: =+N62+O62 -> 0 | U62: 5 | V62: พฤษภาคม | Y62: =+W62+X62 -> 0 | AA62: 5 | AB62: พฤษภาคม | AC62: 0 | AD62: 0 | AE62: =AE12 -> 0 | AF62: =+AC62+AE62 -> 0
A63: 6 | B63: มิถุนายน | H63: =+C63+D63+E63+F63+G63 -> 0 | L63: 6 | M63: มิถุนายน | S63: =+N63+O63 -> 0 | U63: 6 | V63: มิถุนายน | Y63: =+W63+X63 -> 0 | AA63: 6 | AB63: มิถุนายน | AC63: 0 | AD63: 0 | AE63: =AE13 -> 0 | AF63: =+AC63+AE63 -> 0
A64: 7 | B64: กรกฎาคม | H64: =+C64+D64+E64+F64+G64 -> 0 | L64: 7 | M64: กรกฎาคม | S64: =+N64+O64 -> 0 | U64: 7 | V64: กรกฎาคม | Y64: =+W64+X64 -> 0 | AA64: 7 | AB64: กรกฎาคม | AC64: 0 | AD64: 0 | AE64: =AE14 -> 0 | AF64: =+AC64+AE64 -> 0
A65: 8 | B65: สิงหาคม | H65: =+C65+D65+E65+F65+G65 -> 0 | L65: 8 | M65: สิงหาคม | S65: =+N65+O65 -> 0 | U65: 8 | V65: สิงหาคม | Y65: =+W65+X65 -> 0 | AA65: 8 | AB65: สิงหาคม | AC65: 0 | AD65: 0 | AE65: =AE15 -> 0 | AF65: =+AC65+AE65 -> 0
A66: 9 | B66: กันยายน | H66: =+C66+D66+E66+F66+G66 -> 0 | L66: 9 | M66: กันยายน | S66: =+N66+O66 -> 0 | U66: 9 | V66: กันยายน | Y66: =+W66+X66 -> 0 | AA66: 9 | AB66: กันยายน | AC66: 0 | AD66: 0 | AE66: =AE16 -> 0 | AF66: =+AC66+AE66 -> 0
...

Sheet กุมภาพันธ์
A1: รายการขายสินค้า BWP เป็นผู้ผลิต
A2: บจก.ที.ซี.ฟาร์มาซูติคอล อุตสาหกรรม
A3: วันที่ | B3: ขนาด | C3: จำนวน(กก.) | D3: ราคา | E3: มูลค่าก่อน VAT | F3: VAT | G3: มูลค่ารวม VAT
A4: 28/02/69 | B4: 31 cm. x 50 mc. | C4: 464.95 | D4: 52 | E4: =+C4*D4 -> 24177.4 | F4: =+E4*7% -> 1692.418 | G4: =+E4+F4 -> 25869.818 | H4: 6902320
A5: 12/02/69 | B5: 34 cm. x 45 mc. | C5: 1863.3 | D5: 52 | E5: =+C5*D5 -> 96891.6 | F5: =+E5*7% -> 6782.412 | G5: =+E5+F5 -> 103674.01 | H5: 6902132
A6: 03/02/69 | B6: 49 cm. x 45mc.(สูตร 1) | C6: 483.2 | D6: 52 | E6: =+C6*D6 -> 25126.4 | F6: =+E6*7% -> 1758.848 | G6: =+E6+F6 -> 26885.248 | H6: 6902030
A7: 03/02/69 | B7: 49 cm. x 45mc.(สูตร 1) | C7: 499.05 | D7: 52 | E7: =+C7*D7 -> 25950.6 | F7: =+E7*7% -> 1816.542 | G7: =+E7+F7 -> 27767.142 | H7: 6902021
A8: 02/02/69 | B8: 54 cm. x 45 mc. | C8: 4797.3 | D8: 52 | E8: =+C8*D8 -> 249459.6 | F8: =+E8*7% -> 17462.172 | G8: =+E8+F8 -> 266921.77 | H8: 6902006
A9: 03/02/69 | B9: 54 cm. x 45 mc. | C9: 4793.49 | D9: 52 | E9: =+C9*D9 -> 249261.48 | F9: =+E9*7% -> 17448.304 | G9: =+E9+F9 -> 266709.78 | H9: 6902019
A10: 05/02/69 | B10: 54 cm. x 45 mc. | C10: 4783.67 | D10: 52 | E10: =+C10*D10 -> 248750.84 | F10: =+E10*7% -> 17412.559 | G10: =+E10+F10 -> 266163.4 | H10: 6902050
A11: 10/02/69 | B11: 54 cm. x 45 mc. | C11: 4793.64 | D11: 52 | E11: =+C11*D11 -> 249269.28 | F11: =+E11*7% -> 17448.85 | G11: =+E11+F11 -> 266718.13 | H11: 6902102
A12: 11/02/69 | B12: 54 cm. x 45 mc. | C12: 4799.3 | D12: 52 | E12: =+C12*D12 -> 249563.6 | F12: =+E12*7% -> 17469.452 | G12: =+E12+F12 -> 267033.05 | H12: 6902107
A13: 13/02/69 | B13: 54 cm. x 45 mc. | C13: 4791.09 | D13: 52 | E13: =+C13*D13 -> 249136.68 | F13: =+E13*7% -> 17439.568 | G13: =+E13+F13 -> 266576.25 | H13: 6902150
A14: 17/02/69 | B14: 54 cm. x 45 mc. | C14: 4785.48 | D14: 52 | E14: =+C14*D14 -> 248844.96 | F14: =+E14*7% -> 17419.147 | G14: =+E14+F14 -> 266264.11 | H14: 6902167
A15: 18/02/69 | B15: 54 cm. x 45 mc. | C15: 4782.93 | D15: 52 | E15: =+C15*D15 -> 248712.36 | F15: =+E15*7% -> 17409.865 | G15: =+E15+F15 -> 266122.23 | H15: 6902185
... A52: 10/02/69 | B52: 58cm x 45mc RB Classic 250ml.MY 2024 | C52: 1981.85 | D52: 104 | E52: =+C52*D52 -> 206112.4 | F52: =+E52*7% -> 14427.868 | G52: =+E52+F52 -> 220540.27 | H52: 6902096
B53: รวม | C53: =SUM(C4:C52) -> 113693.68 | E53: =SUM(E4:E52) -> 6724499.9 | F53: =SUM(F4:F52) -> 470714.99 | G53: =SUM(G4:G52) -> 7195214.9
A56: บจก.ไทยน้ำทิพย์ (คลอง13)
A57: วันที่ | B57: ขนาด | C57: จำนวน(กก.) | D57: ราคา | E57: มูลค่าก่อน VAT | F57: VAT | G57: มูลค่ารวม VAT
A58: 05/02/69 | B58: 38cm. x 55mc. | C58: 2411.75 | D58: 50.12 | E58: =+C58*D58 -> 120876.91 | F58: =+E58*7% -> 8461.3837 | G58: =+E58+F58 -> 129338.29 | H58: 6902057
A59: 12/02/69 | B59: 50 cm. x 70mc. | C59: 1567.15 | D59: 50.12 | E59: =+C59*D59 -> 78545.558 | F59: =+E59*7% -> 5498.1891 | G59: =+E59+F59 -> 84043.747 | H59: 6902128
A60: 17/02/69 | B60: 50 cm. x 75mc. | C60: 2580.75 | D60: 50.12 | E60: =+C60*D60 -> 129347.19 | F60: =+E60*7% -> 9054.3033 | G60: =+E60+F60 -> 138401.49 | H60: 6902182
A61: 07/02/69 | B61: 50 cm. x 80mc. | C61: 5130 | D61: 50.12 | E61: =+C61*D61 -> 257115.6 | F61: =+E61*7% -> 17998.092 | G61: =+E61+F61 -> 275113.69 | H61: 6902076
A62: 20/02/69 | B62: 50 cm. x 80mc. | C62: 3925.95 | D62: 50.12 | E62: =+C62*D62 -> 196768.61 | F62: =+E62*7% -> 13773.803 | G62: =+E62+F62 -> 210542.42 | H62: 6902225
A63: 21/02/69 | B63: 50 cm. x 80mc. | C63: 1055.4 | D63: 50.12 | E63: =+C63*D63 -> 52896.648 | F63: =+E63*7% -> 3702.7654 | G63: =+E63+F63 -> 56599.413 | H63: 6902229
A64: 25/02/69 | B64: 50 cm. x 80mc. | C64: 4960.85 | D64: 50.12 | E64: =+C64*D64 -> 248637.8 | F64: =+E64*7% -> 17404.646 | G64: =+E64+F64 -> 266042.45 | H64: 6902279
A65: 07/02/69 | B65: 57cm. x 75mc. | C65: 4486.8 | D65: 50.12 | E65: =+C65*D65 -> 224878.42 | F65: =+E65*7% -> 15741.489 | G65: =+E65+F65 -> 240619.91 | H65: 6902074
A66: 17/02/69 | B66: 57cm. x 75mc. | C66: 4862.3 | D66: 50.12 | E66: =+C66*D66 -> 243698.48 | F66: =+E66*7% -> 17058.893 | G66: =+E66+F66 -> 260757.37 | H66: 6902181
A67: 06/02/69 | B67: 57cm. x 80mc.(สีแดง) | C67: 5018.35 | D67: 60.12 | E67: =+C67*D67 -> 301703.2 | F67: =+E67*7% -> 21119.224 | G67: =+E67+F67 -> 322822.43 | H67: 6902061
A68: 20/02/69 | B68: 57cm. x 80mc.(สีแดง) | C68: 6103.7 | D68: 60.12 | E68: =+C68*D68 -> 366954.44 | F68: =+E68*7% -> 25686.811 | G68: =+E68+F68 -> 392641.26 | H68: 6902224
A69: 21/02/69 | B69: 57cm. x 80mc.(สีแดง) | C69: 5101.1 | D69: 60.12 | E69: =+C69*D69 -> 306678.13 | F69: =+E69*7% -> 21467.469 | G69: =+E69+F69 -> 328145.6 | H69: 6902228
... A76: 11/02/69 | B76: 84 cm. X 55 mc. | C76: 1330.05 | D76: 50.12 | E76: =+C76*D76 -> 66662.106 | F76: =+E76*7% -> 4666.3474 | G76: =+E76+F76 -> 71328.453 | H76: 6902123
B77: รวม | C77: =SUM(C58:C76) -> 71729.3 | E77: =SUM(E58:E76) -> 3817994.5 | F77: =SUM(F58:F76) -> 267259.62 | G77: =SUM(G58:G76) -> 4085254.1
A79: บจก.ไทยน้ำทิพย์ (โคราช)
A80: วันที่ | B80: ขนาด | C80: จำนวน(กก.) | D80: ราคา | E80: มูลค่าก่อน VAT | F80: VAT | G80: มูลค่ารวม VAT
A81: 27/02/69 | B81: 50cm. x 75mc. | C81: 3059.35 | D81: 50.12 | E81: =+C81*D81 -> 153334.62 | F81: =+E81*7% -> 10733.424 | G81: =+E81+F81 -> 164068.05 | H81: 6902304
A82: 05/02/69 | B82: 50 cm. x 80mc. | C82: 6061.65 | D82: 50.12 | E82: =+C82*D82 -> 303809.9 | F82: =+E82*7% -> 21266.693 | G82: =+E82+F82 -> 325076.59 | H82: 6902055
A83: 09/02/69 | B83: 50cm. x 80mc. | C83: 6014.25 | D83: 50.12 | E83: =+C83*D83 -> 301434.21 | F83: =+E83*7% -> 21100.395 | G83: =+E83+F83 -> 322534.6 | H83: 6902083
A84: 12/02/69 | B84: 50cm. x 80mc. | C84: 6062.05 | D84: 50.12 | E84: =+C84*D84 -> 303829.95 | F84: =+E84*7% -> 21268.096 | G84: =+E84+F84 -> 325098.04 | H84: 6902129
A85: 23/02/69 | B85: 50cm. x 80mc. | C85: 6071 | D85: 50.12 | E85: =+C85*D85 -> 304278.52 | F85: =+E85*7% -> 21299.496 | G85: =+E85+F85 -> 325578.02 | H85: 6902240
...

Sheet ยอดขายรวม กพ.
A1: รายการขายสินค้าประจำเดือน กุมภาพันธ์ 2569 | L1: งานพิมพ์ประจำเดือน กุมภาพันธ์ 2569 | U1: Supplier งานพิมพ์ประจำเดือน กุมภาพันธ์ 2569 | AA1: ถุงคลุม/ชีท ประจำเดือน กุมภาพันธ์ 2569
A2: ลำดับที่ | B2: ลูกค้า | C2: ม้วนใส (กก.) | D2: ม้วนพิมพ์ (กก.) | E2: ถุงคลุม/ชีท (กก.) | F2: ฟิล์มยืด(กก.) | G2: ถุงหลอด(กก.) | H2: รวม (กก.) | I2: หมายเหตุ | L2: ลำดับที่ | M2: ลูกค้า | N2: 1สี (กก.) | O2: 2สี (กก.) | P2: 3สี (กก.) | Q2: 4สี (กก.) | R2: 8สี (กก.) | S2: รวม (กก.) | U2: ลำดับที่ | V2: ลูกค้า | W2: BWP | X2: ว่องไท | Y2: รวม (กก.) | AA2: ลำดับที่ | AB2: ลูกค้า | AC2: ผลิตเอง (กก.) | AD2: จำนวน( ใบ.) | AE2: จ้างภายนอก (กก.) | AF2: รวม (กก.)
A3: 1 | B3: ไทยน้ำทิพย์ | C3: 157577.6 | D3: 0 | E3: 0 | F3: 0 | G3: 0 | H3: =+C3+D3+E3+F3+G3 -> 157577.6 | I3: 157577.6 | J3: =H3-I3 -> 0 | K3: =+H3*100/H52 -> 42.677562 | L3: 1 | N3: 0 | O3: 0 | P3: 0 | Q3: 0 | R3: 0 | S3: =+N3+O3+P3+Q3+R3 -> 0 | T3: =+S3*100/S12 -> #DIV/0! | U3: 1 | W3: 0 | X3: 0 | Y3: =+W3+X3 -> 0 | AA3: 1 | AC3: 0 | AD3: 0 | AE3: 0 | AF3: =+AC3+AE3 -> 0
A4: 2 | B4: ที.ซีฟาร์มาฯ | C4: 0 | D4: 0 | E4: 0 | F4: 0 | G4: 0 | H4: =+C4+D4+E4+F4+G4 -> 0 | I4: 113693.68 | J4: =H4-I4 -> -113693.68 | K4: =+H4*100/H52 -> 0 | L4: 2 | N4: 0 | O4: 0 | P4: 0 | Q4: 0 | R4: 0 | S4: =+N4+O4+P4+Q4+R4 -> 0 | T4: =+S4*100/S12 -> #DIV/0! | U4: 2 | W4: 0 | X4: 0 | Y4: =+W4+X4 -> 0 | AA4: 2 | AC4: 0 | AD4: 0 | AE4: 0 | AF4: =+AC4+AE4 -> 0
A5: 3 | B5: หาดทิพย์ | C5: 59832.07 | D5: 0 | E5: 0 | F5: 0 | G5: 0 | H5: =+C5+D5+E5+F5+G5 -> 59832.07 | I5: 59832.07 | J5: =H5-I5 -> 0 | K5: =+H5*100/H52 -> 16.204631 | L5: 3 | N5: 0 | O5: 0 | P5: 0 | Q5: 0 | R5: 0 | S5: =+N5+O5+P5+Q5+R5 -> 0 | T5: =+S5*100/S12 -> #DIV/0! | U5: 3 | W5: 0 | X5: 0 | Y5: =+W5+X5 -> 0 | AA5: 3 | AC5: 0 | AD5: 0 | AE5: 0 | AF5: =+AC5+AE5 -> 0
A6: 4 | B6: โอสถสภา | C6: 51817 | D6: 0 | E6: 0 | F6: 0 | G6: 0 | H6: =+C6+D6+E6+F6+G6 -> 51817 | I6: 51817 | J6: =H6-I6 -> 0 | K6: =+H6*100/H52 -> 14.033868 | L6: 4 | N6: 0 | O6: 0 | P6: 0 | Q6: 0 | R6: 0 | S6: =+N6+O6+P6+Q6+R6 -> 0 | T6: =+S6*100/S12 -> #DIV/0! | U6: 4 | W6: 0 | X6: 0 | Y6: =+W6+X6 -> 0 | AA6: 4 | AB6: ทรัพย์สุภา อินเตอร์เทรด | AC6: 0 | AD6: 0 | AE6: 0 | AF6: =+AC6+AE6 -> 0
A7: 5 | B7: กรีนสปอต | C7: 0 | D7: 0 | E7: 0 | F7: 0 | G7: 0 | H7: =+C7+D7+E7+F7+G7 -> 0 | I7: 29669.29 | J7: =H7-I7 -> -29669.29 | K7: =+H7*100/H52 -> 0 | L7: 5 | N7: 0 | O7: 0 | P7: 0 | Q7: 0 | R7: 0 | S7: =+N7+O7+P7+Q7+R7 -> 0 | T7: =+S7*100/S12 -> #DIV/0! | U7: 5 | W7: 0 | X7: 0 | Y7: =+W7+X7 -> 0 | AB7: ผลรวม | AC7: =SUM(AC3:AC6) -> 0 | AD7: =SUM(AD3:AD6) -> 0 | AE7: =SUM(AE3:AE6) -> 0 | AF7: =SUM(AF3:AF6) -> 0
A8: 6 | B8: ทิพย์นที (2005) | C8: 20249.1 | D8: 0 | E8: 0 | F8: 0 | G8: 0 | H8: =+C8+D8+E8+F8+G8 -> 20249.1 | I8: 20249.1 | J8: =H8-I8 -> 0 | K8: =+H8*100/H52 -> 5.4841693 | L8: 6 | N8: 0 | O8: 0 | P8: 0 | Q8: 0 | R8: 0 | S8: =+N8+O8+P8+Q8+R8 -> 0 | T8: =+S8*100/S12 -> #DIV/0! | U8: 6 | W8: 0 | X8: 0 | Y8: =+W8+X8 -> 0
A9: 7 | B9: เอ็มเอ็มพี คอร์ปอเรชั่น | C9: 18147.25 | D9: 0 | E9: 0 | F9: 0 | G9: 0 | H9: =+C9+D9+E9+F9+G9 -> 18147.25 | I9: 18147.25 | J9: =H9-I9 -> 0 | K9: =+H9*100/H52 -> 4.9149143 | L9: 7 | N9: 0 | O9: 0 | P9: 0 | Q9: 0 | R9: 0 | S9: =+N9+O9+P9+Q9+R9 -> 0 | T9: =+S9*100/S12 -> #DIV/0! | U9: 7 | W9: 0 | X9: 0 | Y9: =+W9+X9 -> 0
A10: 8 | B10: ฟรีสแลนด์คัมพิน่า | C10: 0 | D10: 16658.34 | E10: 0 | F10: 0 | G10: 0 | H10: =+C10+D10+E10+F10+G10 -> 16658.34 | I10: 16658.34 | J10: =H10-I10 -> 0 | K10: =+H10*100/H52 -> 4.511665 | L10: 8 | N10: 0 | O10: 0 | P10: 0 | Q10: 0 | R10: 0 | S10: =+N10+O10+P10+Q10+R10 -> 0 | T10: =+S10*100/S12 -> #DIV/0! | U10: 8 | W10: 0 | X10: 0 | Y10: =+W10+X10 -> 0
A11: 9 | B11: เสริมสุข | C11: 13145.65 | D11: 0 | E11: 0 | F11: 0 | G11: 0 | H11: =+C11+D11+E11+F11+G11 -> 13145.65 | I11: 13145.65 | J11: =H11-I11 -> 0 | K11: =+H11*100/H52 -> 3.5603049 | L11: 10 | N11: 0 | O11: 0 | P11: 0 | Q11: 0 | R11: 0 | S11: =+N11+O11+P11+Q11+R11 -> 0 | T11: =+S11*100/S12 -> #DIV/0! | U11: 10 | W11: 0 | X11: 0 | Y11: =+W11+X11 -> 0
A12: 10 | B12: แอดวานซ์ โนเลดจ์ เซอร์วิสเซส | C12: 0 | D12: 0 | E12: 0 | F12: 0 | G12: 0 | H12: =+C12+D12+E12+F12+G12 -> 0 | I12: 9956.2 | J12: =H12-I12 -> -9956.2 | K12: =+H12*100/H52 -> 0 | M12: ผลรวม | N12: =SUM(N3:N11) -> 0 | O12: =SUM(O3:O11) -> 0 | P12: =SUM(P3:P11) -> 0 | Q12: =SUM(Q3:Q11) -> 0 | R12: =SUM(R3:R11) -> 0 | S12: =SUM(S3:S11) -> 0 | V12: ผลรวม | W12: =SUM(W3:W11) -> 0 | X12: =SUM(X3:X11) -> 0 | Y12: =SUM(Y3:Y11) -> 0
A13: 11 | B13: โตโยไซกัน | C13: 0 | D13: 0 | E13: 0 | F13: 0 | G13: 0 | H13: =+C13+D13+E13+F13+G13 -> 0 | I13: 9762.9 | J13: =H13-I13 -> -9762.9
A14: 12 | B14: สหกรณ์โคนมหนองโพ | C14: 0 | D14: 0 | E14: 0 | F14: 0 | G14: 0 | H14: =+C14+D14+E14+F14+G14 -> 0 | I14: 7430.5 | J14: =H14-I14 -> -7430.5 | N14: =+N12*100/S12 -> #DIV/0! | O14: =+O12*100/S12 -> #DIV/0! | P14: =+P12*100/S12 -> #DIV/0! | Q14: =+Q12*100/S12 -> #DIV/0! | R14: =+R12*100/S12 -> #DIV/0! | W14: =+W12*100/Y12 -> #DIV/0! | X14: =+X12*100/Y12 -> #DIV/0!
A15: 13 | B15: กรีนสวิลล์ | C15: 7257.7 | D15: 0 | E15: 0 | F15: 0 | G15: 0 | H15: =+C15+D15+E15+F15+G15 -> 7257.7 | I15: 7257.7 | J15: =H15-I15 -> 0
A16: 14 | B16: เซเว่นสตาร์ | C16: 4524.3 | D16: 0 | E16: 0 | F16: 0 | G16: 0 | H16: =+C16+D16+E16+F16+G16 -> 4524.3 | I16: 4524.3 | J16: =H16-I16 -> 0
A17: 15 | B17: สยามไฟเบอร์ซีเมนต์กรุ๊ป | C17: 0 | D17: 0 | E17: 0 | F17: 0 | G17: 0 | H17: =+C17+D17+E17+F17+G17 -> 0 | I17: 4056.4 | J17: =H17-I17 -> -4056.4
A18: 16 | B18: สยามอุตสาหกรรมวัสดุทนไฟ | C18: 0 | D18: 0 | E18: 0 | F18: 0 | G18: 0 | H18: =+C18+D18+E18+F18+G18 -> 0 | I18: 3945.458 | J18: =H18-I18 -> -3945.458
A19: 17 | B19: ขายยาเพ็ญภาค | C19: 2996.25 | D19: 0 | E19: 0 | F19: 0 | G19: 0 | H19: =+C19+D19+E19+F19+G19 -> 2996.25 | I19: 2996.25 | J19: =H19-I19 -> 0
A20: 18 | B20: ปูนซิเมนต์ไทย(ท่าหลวง)(โรงงานเขาวง) | C20: 0 | D20: 0 | E20: 0 | F20: 0 | G20: 0 | H20: =+C20+D20+E20+F20+G20 -> 0 | I20: 2829 | J20: =H20-I20 -> -2829
A21: 19 | B21: ฐิติรัตน์ | C21: 2810.8 | D21: 0 | E21: 0 | F21: 0 | G21: 0 | H21: =+C21+D21+E21+F21+G21 -> 2810.8 | I21: 2810.8 | J21: =H21-I21 -> 0
A22: 20 | B22: ฐิติภัณฑ์ อินเตอร์พลัส | C22: 0 | D22: 0 | E22: 0 | F22: 0 | G22: 0 | H22: =+C22+D22+E22+F22+G22 -> 0 | I22: 2541.55 | J22: =H22-I22 -> -2541.55
A23: 21 | B23: เอ็น พลัส ชัพพลาย | C23: 0 | D23: 0 | E23: 2216 | F23: 0 | G23: 0 | H23: =+C23+D23+E23+F23+G23 -> 2216 | I23: 2216 | J23: =H23-I23 -> 0
A24: 22 | B24: ผลิตภัณฑ์ตราเพชร | C24: 0 | D24: 0 | E24: 0 | F24: 0 | G24: 0 | H24: =+C24+D24+E24+F24+G24 -> 0 | I24: 1994.9 | J24: =H24-I24 -> -1994.9
A25: 23 | B25: สุรใจฟู้ดส์อินดัสทรี | C25: 1975.25 | D25: 0 | E25: 0 | F25: 0 | G25: 0 | H25: =+C25+D25+E25+F25+G25 -> 1975.25 | I25: 1975.25 | J25: =H25-I25 -> 0
A26: 24 | B26: เพชรพาณิชย์ เบฟเวอเรจ | C26: 0 | D26: 0 | E26: 0 | F26: 0 | G26: 0 | H26: =+C26+D26+E26+F26+G26 -> 0 | I26: 1973.9 | J26: =H26-I26 -> -1973.9
... A51: 49 | B51: สุพิศ การพัฒน์ | C51: 0 | D51: 0 | E51: 0 | F51: 117.9 | G51: 0 | H51: =+C51+D51+E51+F51+G51 -> 117.9 | I51: 117.9 | J51: =H51-I51 -> 0
A52: ผลรวม | C52: =SUM(C3:C51) -> 347543.17 | D52: =SUM(D3:D51) -> 16658.34 | E52: =SUM(E3:E51) -> 2574.8 | F52: =SUM(F3:F51) -> 848.1 | G52: =SUM(G3:G51) -> 1603.8 | H52: =SUM(H3:H51) -> 369228.21 | I52: 561976.65 | J52: =H52-I52 -> -192748.44
C54: =+C52*100/H52 -> 94.126928 | D54: =+D52*100/H52 -> 4.511665 | E54: =+E52*100/H52 -> 0.6973465 | F54: =+F52*100/H52 -> 0.22969534 | G54: =+G52*100/H52 -> 0.43436551
A60: สรุปยอดขายแยกประเภทสินค้าประจำปี 2568 | L60: สรุปงานพิมพ์ ประจำปี 2568 | U60: สรุป Supplier งานพิมพ์ ประจำปี 2568 | AA60: ถุงคลุม/ชีท ประจำปี 2568
A61: ลำดับที่ | B61: เดือน | C61: ม้วนใส (กก.) | D61: ม้วนพิมพ์ (กก.) | E61: ถุงคลุม/ชีท (กก.) | F61: ฟิล์มยืด(กก,) | G61: ถุงหลอด(กก.) | H61: รวม (กก.) | I61: หมายเหตุ | L61: ลำดับที่ | M61: เดือน | N61: 1สี (กก.) | O61: 2สี (กก.) | P61: 3สี (กก.) | Q61: 4สี (กก.) | R61: 8สี (กก.) | S61: รวม (กก.) | U61: ลำดับที่ | V61: เดือน | W61: BWP | X61: ว่องไท | Y61: รวม (กก.) | AA61: ลำดับที่ | AB61: ลูกค้า | AC61: ผลิตเอง (กก.) | AD61: จำนวน( ใบ.) | AE61: จ้างภายนอก (กก.) | AF61: รวม (กก.)
A62: 1 | B62: มกราคม | C62: 438464.53 | D62: 108239.81 | E62: 10409.94 | F62: 1826.78 | G62: 0 | H62: =+C62+D62+E62+F62+G62 -> 558941.06 | L62: 1 | M62: มกราคม | N62: 593.65 | O62: 107609.76 | P62: 0 | Q62: 0 | R62: 36.4 | S62: =+N62+O62 -> 108203.41 | U62: 1 | V62: มกราคม | W62: 102484.55 | X62: 5755.26 | Y62: =+W62+X62 -> 108239.81 | AA62: 1 | AB62: มกราคม | AC62: 10409.942 | AD62: 22800 | AE62: 0 | AF62: =+AC62+AE62 -> 10409.942
A63: 2 | B63: กุมภาพันธ์ | H63: =+C63+D63+E63+F63+G63 -> 0 | L63: 2 | M63: กุมภาพันธ์ | S63: =+N63+O63 -> 0 | U63: 2 | V63: กุมภาพันธ์ | Y63: =+W63+X63 -> 0 | AA63: 2 | AB63: กุมภาพันธ์ | AC63: 0 | AD63: 0 | AE63: =AE9 -> 0 | AF63: =+AC63+AE63 -> 0
A64: 3 | B64: มีนาคม | H64: =+C64+D64+E64+F64+G64 -> 0 | L64: 3 | M64: มีนาคม | S64: =+N64+O64 -> 0 | U64: 3 | V64: มีนาคม | Y64: =+W64+X64 -> 0 | AA64: 3 | AB64: มีนาคม | AC64: 0 | AD64: 0 | AE64: =AE10 -> 0 | AF64: =+AC64+AE64 -> 0
A65: 4 | B65: เมษายน | H65: =+C65+D65+E65+F65+G65 -> 0 | L65: 4 | M65: เมษายน | S65: =+N65+O65 -> 0 | U65: 4 | V65: เมษายน | Y65: =+W65+X65 -> 0 | AA65: 4 | AB65: เมษายน | AC65: 0 | AD65: 0 | AE65: =AE11 -> 0 | AF65: =+AC65+AE65 -> 0
A66: 5 | B66: พฤษภาคม | H66: =+C66+D66+E66+F66+G66 -> 0 | L66: 5 | M66: พฤษภาคม | S66: =+N66+O66 -> 0 | U66: 5 | V66: พฤษภาคม | Y66: =+W66+X66 -> 0 | AA66: 5 | AB66: พฤษภาคม | AC66: 0 | AD66: 0 | AE66: =AE12 -> 0 | AF66: =+AC66+AE66 -> 0
A67: 6 | B67: มิถุนายน | H67: =+C67+D67+E67+F67+G67 -> 0 | L67: 6 | M67: มิถุนายน | S67: =+N67+O67 -> 0 | U67: 6 | V67: มิถุนายน | Y67: =+W67+X67 -> 0 | AA67: 6 | AB67: มิถุนายน | AC67: 0 | AD67: 0 | AE67: =AE13 -> 0 | AF67: =+AC67+AE67 -> 0
A68: 7 | B68: กรกฎาคม | H68: =+C68+D68+E68+F68+G68 -> 0 | L68: 7 | M68: กรกฎาคม | S68: =+N68+O68 -> 0 | U68: 7 | V68: กรกฎาคม | Y68: =+W68+X68 -> 0 | AA68: 7 | AB68: กรกฎาคม | AC68: 0 | AD68: 0 | AE68: =AE14 -> 0 | AF68: =+AC68+AE68 -> 0
A69: 8 | B69: สิงหาคม | H69: =+C69+D69+E69+F69+G69 -> 0 | L69: 8 | M69: สิงหาคม | S69: =+N69+O69 -> 0 | U69: 8 | V69: สิงหาคม | Y69: =+W69+X69 -> 0 | AA69: 8 | AB69: สิงหาคม | AC69: 0 | AD69: 0 | AE69: =AE15 -> 0 | AF69: =+AC69+AE69 -> 0
A70: 9 | B70: กันยายน | H70: =+C70+D70+E70+F70+G70 -> 0 | L70: 9 | M70: กันยายน | S70: =+N70+O70 -> 0 | U70: 9 | V70: กันยายน | Y70: =+W70+X70 -> 0 | AA70: 9 | AB70: กันยายน | AC70: 0 | AD70: 0 | AE70: =AE16 -> 0 | AF70: =+AC70+AE70 -> 0
...

Sheet ลำดับ
B1: มกราคม | E1: กุมภาพันธ์ | H1: มีนาคม | K1: เมษายน | N1: พฤษภาคม
B2: บริษัท | C2: จำนวน(กก.) | E2: บริษัท | F2: จำนวน(กก.) | H2: บริษัท | I2: จำนวน(กก.) | K2: บริษัท | L2: จำนวน(กก.) | N2: บริษัท | O2: จำนวน(กก.)
A3: 1 | B3: ไทยน้ำทิพย์ | C3: =มกราคม!C76+มกราคม!C95+มกราคม!C110+มกราคม!C115 -> 151633.46 | D3: 1 | E3: ไทยน้ำทิพย์ | F3: =กุมภาพันธ์!C77+กุมภาพันธ์!C97+กุมภาพันธ์!C107 -> 157577.6 | G3: 1 | H3: ไทยน้ำทิพย์ | I3: =มีนาคม!C91+มีนาคม!C111+มีนาคม!C128 -> 169218.43 | J3: 1 | K3: ไทยน้ำทิพย์ | L3: =เมษายน!C113+เมษายน!C129+เมษายน!C148 -> 207602.08 | M3: 1 | N3: ไทยน้ำทิพย์ | O3: =พฤษภาคม!C92+พฤษภาคม!C108+พฤษภาคม!C124 -> 181757.49
A4: 2 | B4: ที.ซีฟาร์มาฯ | C4: =มกราคม!C55 -> 106756.59 | D4: 2 | E4: ที.ซีฟาร์มาฯ | F4: =กุมภาพันธ์!C53 -> 113693.68 | G4: 2 | H4: ที.ซีฟาร์มาฯ | I4: =มีนาคม!C67 -> 133183.56 | J4: 2 | K4: ที.ซีฟาร์มาฯ | L4: =เมษายน!C76 -> 169426.79 | M4: 2 | N4: ที.ซีฟาร์มาฯ | O4: =พฤษภาคม!C51 -> 162967.37
A5: 3 | B5: หาดทิพย์ | C5: =มกราคม!C154 -> 93627.69 | D5: 3 | E5: หาดทิพย์ | F5: =กุมภาพันธ์!C132 -> 59832.07 | G5: 3 | H5: หาดทิพย์ | I5: =มีนาคม!C201 -> 131868.14 | J5: 3 | K5: หาดทิพย์ | L5: =เมษายน!C193 -> 100224.13 | M5: 3 | N5: โอสถสภา | O5: =พฤษภาคม!C281 -> 58257.7
A6: 4 | B6: โอสถสภา | C6: =มกราคม!C283 -> 42651.8 | D6: 4 | E6: โอสถสภา | F6: =กุมภาพันธ์!C236 -> 51817 | G6: 4 | H6: โอสถสภา | I6: =มีนาคม!C352 -> 55416.7 | J6: 4 | K6: โอสถสภา | L6: =เมษายน!C290 -> 50673 | M6: 4 | N6: หาดทิพย์ | O6: =พฤษภาคม!C154 -> 50830.61
A7: 5 | B7: กรีนสปอต | C7: =มกราคม!C226+มกราคม!E234 -> 36103.35 | D7: 5 | E7: กรีนสปอต | F7: =กุมภาพันธ์!C181 -> 29669.29 | G7: 5 | H7: กรีนสปอต | I7: =มีนาคม!C273+มีนาคม!E282 -> 47678.57 | J7: 5 | K7: กรีนสปอต | L7: =เมษายน!C243 -> 33662.63 | M7: 5 | N7: กรีนสปอต | O7: =พฤษภาคม!C218 -> 48255.41
A8: 6 | B8: ฟรีสแลนด์คัมพิน่า | C8: =มกราคม!C590 -> 16057.48 | D8: 6 | E8: ทิพย์นที (2005) | F8: =กุมภาพันธ์!C585 -> 20249.1 | G8: 6 | H8: ฟรีสแลนด์คัมพิน่า | I8: =มีนาคม!C592 -> 14388.91 | J8: 6 | K8: เสริมสุข | L8: =เมษายน!C312+เมษายน!C319+เมษายน!C325+เมษายน!C331 -> 24339.85 | M8: 6 | N8: เสริมสุข | O8: =พฤษภาคม!C294+พฤษภาคม!C305+พฤษภาคม!C310+พฤษภาคม!C316 -> 26641.15
A9: 7 | B9: ทิพย์นที (2005) | C9: =มกราคม!C598 -> 14973.45 | D9: 7 | E9: เอ็มเอ็มพี คอร์ปอเรชั่น | F9: =กุมภาพันธ์!E397+กุมภาพันธ์!C415 -> 18147.25 | G9: 7 | H9: โตโยไซกัน | I9: =มีนาคม!C393+มีนาคม!C403+มีนาคม!C432 -> 13307.25 | J9: 7 | K9: โตโยไซกัน | L9: =เมษายน!C361+เมษายน!C388 -> 22757.4 | M9: 7 | N9: ทิพย์นที (2005) | O9: =พฤษภาคม!C560 -> 18313.05
A10: 8 | B10: โตโยไซกัน | C10: =มกราคม!C339+มกราคม!C374 -> 14359.08 | D10: 8 | E10: ฟรีสแลนด์คัมพิน่า | F10: =กุมภาพันธ์!C576 -> 16658.34 | G10: 8 | H10: เสริมสุข | I10: =มีนาคม!C367+มีนาคม!C374 -> 8923.4 | J10: 8 | K10: ฟรีสแลนด์คัมพิน่า | L10: =เมษายน!C553 -> 13143.23 | M10: 8 | N10: ฟรีสแลนด์คัมพิน่า | O10: =พฤษภาคม!C551 -> 12471.69
A11: 9 | B11: เสริมสุข | C11: =มกราคม!C297+มกราคม!C302+มกราคม!C307 -> 12205.4 | D11: 9 | E11: เสริมสุข | F11: =กุมภาพันธ์!C256+กุมภาพันธ์!C262 -> 13145.65 | G11: 9 | H11: เซเว่นสตาร์ | I11: =มีนาคม!C475+มีนาคม!C492 -> 6181.45 | J11: 9 | K11: อินคาวอเตอร์ | L11: =เมษายน!C657 -> 11889.9 | M11: 9 | N11: โตโยไซกัน | O11: =พฤษภาคม!C349+พฤษภาคม!C359+พฤษภาคม!C384 -> 11850.55
A12: 10 | B12: สหกรณ์โคนมหนองโพ | C12: =มกราคม!C319 -> 7961.1 | D12: 10 | E12: แอดวานซ์ โนเลดจ์ เซอร์วิสเซส | F12: =กุมภาพันธ์!C543 -> 9956.2 | G12: 10 | H12: สหกรณ์โคนมหนองโพ | I12: =มีนาคม!C361 -> 5999.4 | J12: 10 | K12: กรีนสวิลล์ | L12: =เมษายน!C418 -> 9573.8 | M12: 10 | N12: สยามอุตสาหกรรมวัสดุทนไฟ | O12: =พฤษภาคม!F479 -> 8349.98
B13: กรีนสวิลล์ | C13: =มกราคม!C410 -> 7209.95 | E13: โตโยไซกัน | F13: =กุมภาพันธ์!C289+กุมภาพันธ์!C302+กุมภาพันธ์!C328 -> 9762.9 | H13: เอ็มเอ็มพี คอร์ปอเรชั่น | I13: =มีนาคม!C441 -> 5907.55 | K13: ทิพย์นที (2005) | L13: =เมษายน!C560 -> 9551.15 | N13: สหกรณ์โคนมหนองโพ | O13: =พฤษภาคม!C328 -> 7208.6
B14: เอ็มเอ็มพี คอร์ปอเรชั่น | C14: =มกราคม!C448 -> 6263.1 | E14: สหกรณ์โคนมหนองโพ | F14: =กุมภาพันธ์!C271 -> 7430.5 | H14: กรีนสวิลล์ | I14: =มีนาคม!C470 -> 5684.15 | K14: สเปซ วอเตอร์ | L14: =เมษายน!C686 -> 8634.35 | N14: กรีนสวิลล์ | O14: =พฤษภาคม!C413 -> 6036.4
B15: สยามอุตสาหกรรมวัสดุทนไฟ | C15: =มกราคม!F472 -> 5361.992 | E15: กรีนสวิลล์ | F15: =กุมภาพันธ์!C363 -> 7257.7 | H15: แอดวานซ์ โนเลดจ์ เซอร์วิสเซส | I15: =มีนาคม!C623 -> 4962.37 | K15: เอ็มเอ็มพี คอร์ปอเรชั่น | L15: =เมษายน!C455 -> 5983.25 | N15: อินคาวอเตอร์ | O15: =พฤษภาคม!C659 -> 5982.95
B16: แอดวานซ์ โนเลดจ์ เซอร์วิสเซส | C16: =มกราคม!C554 -> 4941.7 | E16: เซเว่นสตาร์ | F16: =กุมภาพันธ์!C381 -> 4524.3 | H16: สยามอุตสาหกรรมวัสดุทนไฟ | I16: =มีนาคม!F549 -> 4909.7008 | K16: สยามไฟเบอร์ซีเมนต์กรุ๊ป | L16: =เมษายน!C648 -> 5019.25 | N16: Lao Coca-Col | O16: =พฤษภาคม!C129 -> 5976.1
B17: เอ็น พลัส ชัพพลาย | C17: =มกราคม!E334 -> 4432 | E17: สยามไฟเบอร์ซีเมนต์กรุ๊ป | F17: =กุมภาพันธ์!C713 -> 4056.4 | H17: ทิพย์นที (2005) | I17: =มีนาคม!C633 -> 4701.8 | K17: เซเว่นสตาร์ | L17: =เมษายน!C423+เมษายน!C440 -> 4707.9 | N17: ผลิตภัณฑ์ตราเพชร | O17: =พฤษภาคม!C578 -> 4971.1
B18: ขายยาเพ็ญภาค | C18: =มกราคม!C292 -> 3929.85 | E18: สยามอุตสาหกรรมวัสดุทนไฟ | F18: =กุมภาพันธ์!F454 -> 3945.458 | H18: เพชรพาณิชย์ เบฟเวอเรจ | I18: =มีนาคม!C664 -> 4118.5 | K18: ขายยาเพ็ญภาค | L18: =เมษายน!C299 -> 4562.15 | N18: พลอยพรรณราย อินดัสตรี | O18: =พฤษภาคม!C520 -> 3885.05
B19: สยามไฟเบอร์ซีเมนต์กรุ๊ป | C19: =มกราคม!C647 -> 3586.2 | E19: ขายยาเพ็ญภาค | F19: =กุมภาพันธ์!C243 -> 2996.25 | H19: ฐิติรัตน์ | I19: =มีนาคม!C658 -> 3987.95 | K19: ปูนซิเมนต์ไทย(ท่าหลวง)(โรงงานเขาวง) | L19: =เมษายน!C461+เมษายน!F471 -> 3807.85 | N19: ขายยาเพ็ญภาค | O19: =พฤษภาคม!C288 -> 2994.75
B20: เซเว่นสตาร์ | C20: =มกราคม!C427 -> 3459.3 | E20: ปูนซิเมนต์ไทย(ท่าหลวง)(โรงงานเขาวง) | F20: =กุมภาพันธ์!F426 -> 2829 | H20: เถิงธงพานิชย์ | I20: =มีนาคม!C563 -> 3488.05 | K20: ผลิตภัณฑ์ตราเพชร | L20: =เมษายน!C575+เมษายน!C581 -> 3785.5 | N20: ชิโคะคุ | O20: =พฤษภาคม!C333 -> 2969.05
B21: เถิงธงพานิชย์ | C21: =มกราคม!C495 -> 2747.6 | E21: ฐิติรัตน์ | F21: =กุมภาพันธ์!C627 -> 2810.8 | H21: ฐิติภัณฑ์ อินเตอร์พลัส | I21: =มีนาคม!E519+มีนาคม!C534 -> 3158.85 | K21: เพ็ญภาคไวเนอรี่ | L21: =เมษายน!C306 -> 2980.55 | N21: เพชรพาณิชย์ เบฟเวอเรจ | O21: =พฤษภาคม!C591 -> 2927.95
B22: ซันสวีท | C22: =มกราคม!C488 -> 2566.65 | E22: ฐิติภัณฑ์ อินเตอร์พลัส | F22: =กุมภาพันธ์!C439 -> 2541.55 | H22: ปูนซิเมนต์ไทย(ท่าหลวง)(โรงงานเขาวง) | I22: =มีนาคม!F510 -> 2829 | K22: ชิโคะคุ | L22: =เมษายน!C343 -> 2581.95 | N22: ฐิติภัณฑ์ อินเตอร์พลัส | O22: =พฤษภาคม!C455 -> 2701.6
B23: พลอยพรรณราย อินดัสตรี | C23: =มกราคม!C529 -> 2560.55 | E23: เอ็น พลัส ชัพพลาย | F23: =กุมภาพันธ์!E283 -> 2216 | H23: เอ็น พลัส ชัพพลาย | I23: =มีนาคม!E386 -> 2216 | K23: ฐิติภัณฑ์ อินเตอร์พลัส | L23: =เมษายน!C482 -> 2544.05 | N23: เถิงธง | O23: =พฤษภาคม!C506 -> 2573.7
B24: สุรใจฟู้ดส์อินดัสทรี | C24: =มกราคม!C516 -> 2378.5 | E24: ผลิตภัณฑ์ตราเพชร | F24: =กุมภาพันธ์!C592 -> 1994.9 | H24: ขายยาเพ็ญภาค | I24: =มีนาคม!C289 -> 2161.6 | K24: สหกรณ์โคนมหนองโพ | L24: =เมษายน!C337 -> 2489.8 | N24: ยูนิ-เพรสซิเดนท์ | O24: =พฤษภาคม!C566 -> 2081.4
B25: ฐิติภัณฑ์ อินเตอร์พลัส | C25: =มกราคม!C456 -> 1972 | E25: สุรใจฟู้ดส์อินดัสทรี | F25: =กุมภาพันธ์!C495 -> 1975.25 | H25: สยามไฟเบอร์ซีเมนต์กรุ๊ป | I25: =มีนาคม!C718 -> 2104.25 | K25: ไบเออร์สด๊อฟ | L25: =เมษายน!C612 -> 2447 | N25: ซันสวีท | O25: =พฤษภาคม!C491 -> 1952.45
B26: เพชรพาณิชย์ เบฟเวอเรจ | C26: =มกราคม!C608 -> 1951.65 | E26: เพชรพาณิชย์ เบฟเวอเรจ | F26: =กุมภาพันธ์!C633 -> 1973.9 | H26: จอมธนา | I26: =มีนาคม!C687 -> 1983.75 | K26: จอมธนา | L26: =เมษายน!C630 -> 2078.85 | N26: เซเว่นสตาร์ | O26: =พฤษภาคม!C418+พฤษภาคม!C429 -> 1792.65
B27: ทิปโก้ | C27: =มกราคม!C439 -> 1589.6 | E27: Beiedorf (Thailand) | F27: =กุมภาพันธ์!C680 -> 1603.8 | H27: สุรใจฟู้ดส์อินดัสทรี | I27: =มีนาคม!C612 -> 1971.35 | K27: เอ็น พลัส ชัพพลาย | L27: =เมษายน!E351 -> 1994.4 | N27: ที.ที.วิน เอ็นจิเนียริ่ง | O27: =พฤษภาคม!C526 -> 1771
B28: จอมธนา | C28: =มกราคม!C627 -> 1408.34 | E28: พลอยพรรณราย อินดัสตรี | F28: =กุมภาพันธ์!C502 -> 1364.85 | H28: อินคาวอเตอร์ | I28: =มีนาคม!C759 -> 1915.75 | K28: สุรใจฟู้ดส์อินดัสทรี | L28: =เมษายน!C521 -> 1549.5 | N28: เอ็น พลัส ชัพพลาย | O28: =พฤษภาคม!E340 -> 1551.2
B29: ชิโคะคุ | C29: =มกราคม!C324 -> 1034.15 | E29: ทิปโก้ | F29: =กุมภาพันธ์!C390 -> 1222.25 | H29: พลอยพรรณราย อินดัสตรี | I29: =มีนาคม!C618 -> 1438.65 | K29: เจ.เอส.อุตสาหกรรมพลาสติก | L29: =เมษายน!C619 -> 1463.25 | N29: สุรใจฟู้ดส์อินดัสทรี | O29: =พฤษภาคม!C497 -> 1028.9
B30: ยูนิ-เพรสซิเดนท์ | C30: =มกราคม!C603 -> 1026.5 | E30: ลัคซูรี่ ดีไวซ์ | F30: =กุมภาพันธ์!F643 -> 1076.4 | H30: ชิโคะคุ | I30: =มีนาคม!C379 -> 1043.35 | K30: พลอยพรรณราย อินดัสตรี | L30: =เมษายน!C527 -> 1387.8 | N30: พรีมา เบฟเวอเรจ | O30: =พฤษภาคม!E682 -> 994.7385
B31: เจ.เอส.อุตสาหกรรมพลาสติก | C31: =มกราคม!C708 -> 492.2 | E31: ชิโคะคุ | F31: =กุมภาพันธ์!C276 -> 1043.25 | H31: ยูนิ-เพรสซิเดนท์ | I31: =มีนาคม!C638 -> 1025.65 | K31: สยามอุตสาหกรรมวัสดุทนไฟ | L31: =เมษายน!F499 -> 994.68 | N31: จอมธนา | O31: =พฤษภาคม!C610 -> 940.6
B32: ที.ที.วิน เอ็นจิเนียริ่ง | C32: =มกราคม!C559 -> 460.75 | E32: พิริยะพลาส | F32: =กุมภาพันธ์!C667 -> 1015.9 | H32: ซันสวีท | I32: =มีนาคม!C524 -> 972.7 | K32: ลวดเชื่อมไทยฮันซ่า | L32: =เมษายน!C663 -> 974.35 | N32: ปูนซิเมนต์ไทย(ท่าหลวง)(โรงงานเขาวง) | O32: =พฤษภาคม!F442 -> 825
B33: ไวตาสกายเทคโนโลยีความแม่นยำ (ประเทศไทย) | C33: =มกราคม!C522 -> 390.35 | E33: จอมธนา | F33: =กุมภาพันธ์!C672 -> 994.4 | H33: ซีน่า วอเตอร์ | I33: =มีนาคม!C692 -> 812.6 | K33: เมทเทิล เมท | L33: =เมษายน!C681 -> 969.5 | N33: นอริตาเก้ เอสซีจี พลาสเตอร์ | O33: =พฤษภาคม!E701 -> 663
B34: น้ำมันบริโภค | C34: =มกราคม!C641 -> 386.6 | E34: จี-แฟน โกรอิง | F34: =กุมภาพันธ์!F535 -> 713.0142 | H34: ผลิตภัณฑ์ตราเพชร | I34: =มีนาคม!C643 -> 712.6 | K34: ฐิติรัตน์ | L34: =เมษายน!C601 -> 967.96 | N34: โพลิเมอร์เอเชีย | O34: =พฤษภาคม!E653 -> 621
B35: เอสซีจี เซรามิกส์ | C35: =มกราคม!F503 -> 364.8 | E35: ซันสวีท | F35: =กุมภาพันธ์!C468 -> 702.1 | H35: น้ำดื่ม เอสเอ็ม | I35: =มีนาคม!C724 -> 647.25 | K35: ยูนิ-เพรสซิเดนท์ | L35: =เมษายน!C565 -> 876.75 | N35: น้ำมันบริโภค | O35: =พฤษภาคม!C632 -> 589.45
B36: THAI NISSHIN SEIFUN | C36: =มกราคม!C620 -> 286.15 | E36: THAI NISSHIN SEIFUN | F36: =กุมภาพันธ์!C686 -> 604.7 | H36: โพลิเมอร์เอเชีย | I36: =มีนาคม!E743 -> 621 | K36: ทิปโก้ | L36: =เมษายน!C448 -> 766.45 | N36: สยามกลาสอยุธยา | O36: =พฤษภาคม!F625 -> 502.3
B37: ธาริน แอพไพรซัล | C37: =มกราคม!C664 -> 252.45 | E37: แม็คคอร์มิค | F37: =กุมภาพันธ์!C735 -> 590.8 | H37: ที.ที.วิน เอ็นจิเนียริ่ง | I37: =มีนาคม!C628 -> 506.65 | K37: สยาม แกรนด์-เทค | L37: =เมษายน!E596 -> 600 | N37: โรงงานแม่รวย | O37: =พฤษภาคม!C600 -> 492.65
B38: สยามกลาสอยุธยา | C38: =มกราคม!F634 -> 251.15 | E38: สยามกลาสอยุธยา | F38: =กุมภาพันธ์!F703 -> 502.3 | H38: เจ.เอส.อุตสาหกรรมพลาสติก | I38: =มีนาคม!C676 -> 455 | K38: ทรัพย์สุภา อินเตอร์เทรด | L38: =เมษายน!E588 -> 598 | N38: ลัคซูรี่ ดิไวซ์ | O38: =พฤษภาคม!F675 -> 331.4
B39: เยื่อไผ่ พริ้นติ้ง | C39: =มกราคม!E690 -> 248.4 | E39: โรงงานแม่รวย | F39: =กุมภาพันธ์!C654 -> 495.5 | H39: ทิปโก้ | I39: =มีนาคม!C499 -> 452.8 | K39: ซันสวีท | L39: =เมษายน!C509 -> 434.8 | N39: คิงสเตลล่า กรุ๊ป | O39: =พฤษภาคม!E666 -> 331.2
B40: พิริยะพลาส | C40: =มกราคม!E615 -> 248.4 | E40: เอสซีจี เซรามิกส์ | F40: =กุมภาพันธ์!F482 -> 364.8 | H40: ปิยวัฒน์ซีเมนต์บล็อค | I40: =มีนาคม!E650 -> 315.2 | K40: ลัคซูรี่ ดิไวซ์ | L40: =เมษายน!F709 -> 331.4 | N40: นายณัฐพงษ์ มินา | O40: =พฤษภาคม!C605 -> 324.5
...

Sheet มีนาคม
A1: รายการขายสินค้า BWP เป็นผู้ผลิต
A2: บจก.ที.ซี.ฟาร์มาซูติคอล อุตสาหกรรม
A3: วันที่ | B3: ขนาด | C3: จำนวน(กก.) | D3: ราคา | E3: มูลค่าก่อน VAT | F3: VAT | G3: มูลค่ารวม VAT
A4: 03/03/69 | B4: 49 cm. x 45mc.(สูตร 1) | C4: 495.6 | D4: 52 | E4: =+C4*D4 -> 25771.2 | F4: =+E4*7% -> 1803.984 | G4: =+E4+F4 -> 27575.184 | I4: 6903025
A5: 21/03/69 | B5: 50 cm. x 55mc. | C5: 995.5 | D5: 52 | E5: =+C5*D5 -> 51766 | F5: =+E5*7% -> 3623.62 | G5: =+E5+F5 -> 55389.62 | I5: 6903267
A6: 03/03/69 | B6: 54 cm. x 45 mc. | C6: 4799.09 | D6: 52 | E6: =+C6*D6 -> 249552.68 | F6: =+E6*7% -> 17468.688 | G6: =+E6+F6 -> 267021.37 | I6: 6903026
A7: 05/03/69 | B7: 54 cm. x 45 mc. | C7: 4793.14 | D7: 52 | E7: =+C7*D7 -> 249243.28 | F7: =+E7*7% -> 17447.03 | G7: =+E7+F7 -> 266690.31 | I7: 6903055
A8: 06/03/69 | B8: 54 cm. x 45 mc. | C8: 4788.154 | D8: 52 | E8: =+C8*D8 -> 248984.01 | F8: =+E8*7% -> 17428.881 | G8: =+E8+F8 -> 266412.89 | I8: 6903077
A9: 10/03/69 | B9: 54 cm. x 45 mc. | C9: 4778.45 | D9: 52 | E9: =+C9*D9 -> 248479.4 | F9: =+E9*7% -> 17393.558 | G9: =+E9+F9 -> 265872.96 | I9: 6903113
A10: 11/03/69 | B10: 54 cm. x 45 mc. | C10: 4605.08 | D10: 52 | E10: =+C10*D10 -> 239464.16 | F10: =+E10*7% -> 16762.491 | G10: =+E10+F10 -> 256226.65 | I10: 6903128
A11: 13/03/69 | B11: 54 cm. x 45 mc. | C11: 4780.34 | D11: 52 | E11: =+C11*D11 -> 248577.68 | F11: =+E11*7% -> 17400.438 | G11: =+E11+F11 -> 265978.12 | I11: 6903168
A12: 14/03/69 | B12: 54 cm. x 45 mc. | C12: 4786.56 | D12: 52 | E12: =+C12*D12 -> 248901.12 | F12: =+E12*7% -> 17423.078 | G12: =+E12+F12 -> 266324.2 | I12: 6903185
A13: 16/03/69 | B13: 54 cm. x 45 mc. | C13: 4795.28 | D13: 52 | E13: =+C13*D13 -> 249354.56 | F13: =+E13*7% -> 17454.819 | G13: =+E13+F13 -> 266809.38 | I13: 6903191
A14: 17/03/69 | B14: 54 cm. x 45 mc. | C14: 4794.77 | D14: 52 | E14: =+C14*D14 -> 249328.04 | F14: =+E14*7% -> 17452.963 | G14: =+E14+F14 -> 266781 | I14: 6903204
A15: 18/03/69 | B15: 54 cm. x 45 mc. | C15: 4785.14 | D15: 52 | E15: =+C15*D15 -> 248827.28 | F15: =+E15*7% -> 17417.91 | G15: =+E15+F15 -> 266245.19 | I15: 6903212
... A66: 18/03/69 | B66: 58cm x 45mc RB Classic 250ml.MY 2024 | C66: 999.4 | D66: 104 | E66: =+C66*D66 -> 103937.6 | F66: =+E66*7% -> 7275.632 | G66: =+E66+F66 -> 111213.23 | I66: 6903213
B67: รวม | C67: =SUM(C4:C66) -> 133183.56 | E67: =SUM(E4:E66) -> 7804049 | F67: =SUM(F4:F66) -> 546283.43 | G67: =SUM(G4:G66) -> 8350332.5
A69: บจก.ไทยน้ำทิพย์ (คลอง13)
A70: วันที่ | B70: ขนาด | C70: จำนวน(กก.) | D70: ราคา | E70: มูลค่าก่อน VAT | F70: VAT | G70: มูลค่ารวม VAT
A71: 10/03/69 | B71: 38cm. x 55mc. | C71: 2068.45 | D71: 50.12 | E71: =+C71*D71 -> 103670.71 | F71: =+E71*7% -> 7256.95 | G71: =+E71+F71 -> 110927.66 | I71: 6903112
A72: 06/03/69 | B72: 50 cm. x 70mc. | C72: 2498.35 | D72: 50.12 | E72: =+C72*D72 -> 125217.3 | F72: =+E72*7% -> 8765.2111 | G72: =+E72+F72 -> 133982.51 | I72: 6903087
A73: 09/03/69 | B73: 50 cm. x 75mc. | C73: 2532.35 | D73: 50.12 | E73: =+C73*D73 -> 126921.38 | F73: =+E73*7% -> 8884.4967 | G73: =+E73+F73 -> 135805.88 | I73: 6903098
A74: 24/03/69 | B74: 50 cm. x 75mc. | C74: 2485.1 | D74: 54 | E74: =+C74*D74 -> 134195.4 | F74: =+E74*7% -> 9393.678 | G74: =+E74+F74 -> 143589.08 | I74: 6903300
A75: 02/03/69 | B75: 50 cm. x 80mc. | C75: 4998.35 | D75: 50.12 | E75: =+C75*D75 -> 250517.3 | F75: =+E75*7% -> 17536.211 | G75: =+E75+F75 -> 268053.51 | I75: 6903019
A76: 09/03/69 | B76: 50 cm. x 80mc. | C76: 3026 | D76: 50.12 | E76: =+C76*D76 -> 151663.12 | F76: =+E76*7% -> 10616.418 | G76: =+E76+F76 -> 162279.54 | I76: 6903097
A77: 07/03/69 | B77: 50 cm. x 80mc. | C77: 2517.85 | D77: 50.12 | E77: =+C77*D77 -> 126194.64 | F77: =+E77*7% -> 8833.6249 | G77: =+E77+F77 -> 135028.27 | I77: 6903091
A78: 12/03/69 | B78: 50 cm. x 80mc. | C78: 4828.8 | D78: 50.12 | E78: =+C78*D78 -> 242019.46 | F78: =+E78*7% -> 16941.362 | G78: =+E78+F78 -> 258960.82 | I78: 6903153
A79: 16/03/69 | B79: 50 cm. x 80mc. | C79: 4669.35 | D79: 50.12 | E79: =+C79*D79 -> 234027.82 | F79: =+E79*7% -> 16381.948 | G79: =+E79+F79 -> 250409.77 | I79: 6903199
A80: 25/03/69 | B80: 50 cm. x 80mc. | C80: 4985.8 | D80: 54 | E80: =+C80*D80 -> 269233.2 | F80: =+E80*7% -> 18846.324 | G80: =+E80+F80 -> 288079.52 | I80: 6903322
A81: 26/03/69 | B81: 50 cm. x 80mc. | C81: 5086.5 | D81: 54 | E81: =+C81*D81 -> 274671 | F81: =+E81*7% -> 19226.97 | G81: =+E81+F81 -> 293897.97 | I81: 6903325
A82: 04/03/69 | B82: 50cm. x 75mc. (สีแดง) | C82: 1020.45 | D82: 60.12 | E82: =+C82*D82 -> 61349.454 | F82: =+E82*7% -> 4294.4618 | G82: =+E82+F82 -> 65643.916 | I82: 6903051
... A90: 24/03/69 | B90: 76 cm. X 55 mc. | C90: 2543.45 | D90: 54 | E90: =+C90*D90 -> 137346.3 | F90: =+E90*7% -> 9614.241 | G90: =+E90+F90 -> 146960.54 | I90: 6903301
B91: รวม | C91: =SUM(C71:C90) -> 76200.1 | E91: =SUM(E71:E90) -> 4289880.2 | F91: =SUM(F71:F90) -> 300291.62 | G91: =SUM(G71:G90) -> 4590171.8
A93: บจก.ไทยน้ำทิพย์ (โคราช)
A94: วันที่ | B94: ขนาด | C94: จำนวน(กก.) | D94: ราคา | E94: มูลค่าก่อน VAT | F94: VAT | G94: มูลค่ารวม VAT
A95: 10/03/69 | B95: 50cm. x 75mc. | C95: 3038.75 | D95: 50.12 | E95: =+C95*D95 -> 152302.15 | F95: =+E95*7% -> 10661.15 | G95: =+E95+F95 -> 162963.3 | I95: 6903109
A96: 18/03/69 | B96: 50cm. x 75mc. | C96: 3108.6 | D96: 54 | E96: =+C96*D96 -> 167864.4 | F96: =+E96*7% -> 11750.508 | G96: =+E96+F96 -> 179614.91 | I96: 6903211
A97: 27/03/69 | B97: 50cm. x 75mc. | C97: 3084.45 | D97: 54 | E97: =+C97*D97 -> 166560.3 | F97: =+E97*7% -> 11659.221 | G97: =+E97+F97 -> 178219.52 | I97: 6903339
A98: 30/03/69 | B98: 50cm. x 80mc. | C98: 3046 | D98: 54 | E98: =+C98*D98 -> 164484 | F98: =+E98*7% -> 11513.88 | G98: =+E98+F98 -> 175997.88 | I98: 6903363
A99: 25/03/69 | B99: 52cm. x 80mc. | C99: 2703.95 | D99: 54 | E99: =+C99*D99 -> 146013.3 | F99: =+E99*7% -> 10220.931 | G99: =+E99+F99 -> 156234.23 | I99: 6903304
...

Sheet ยอดขายรวม มีค.
A1: รายการขายสินค้าประจำเดือน มีนาคม 2569 | L1: งานพิมพ์ประจำเดือน มีนาคม 2569 | V1: Supplier งานพิมพ์ประจำเดือน มีนาคม 2569 | AB1: ถุงคลุม/ชีท ประจำเดือน มีนาคม 2569
A2: ลำดับที่ | B2: ลูกค้า | C2: ม้วนใส (กก.) | D2: ม้วนพิมพ์ (กก.) | E2: ถุงคลุม/ชีท (กก.) | F2: ฟิล์มยืด(กก.) | G2: ถุงหลอด(กก.) | H2: รวม (กก.) | I2: หมายเหตุ | L2: ลำดับที่ | M2: ลูกค้า | N2: 1สี (กก.) | O2: 2สี (กก.) | P2: 3สี (กก.) | Q2: 4สี (กก.) | R2: 6สี (กก.) | S2: 8สี (กก.) | T2: รวม (กก.) | V2: ลำดับที่ | W2: ลูกค้า | X2: BWP | Y2: ว่องไท | Z2: รวม (กก.) | AB2: ลำดับที่ | AC2: ลูกค้า | AD2: ผลิตเอง (กก.) | AE2: จำนวน( ใบ.) | AF2: จ้างภายนอก (กก.) | AG2: รวม (กก.)
A3: 1 | B3: ไทยน้ำทิพย์ | C3: 169218.43 | D3: 0 | E3: 0 | F3: 0 | G3: 0 | H3: =+C3+D3+E3+F3+G3 -> 169218.43 | J3: =+H3*100/H52 -> 25.900563 | L3: 1 | M3: ที.ซีฟาร์มาฯ | N3: 0 | O3: 38312.66 | P3: 0 | Q3: 0 | R3: 4475.2 | S3: 0 | T3: =N3+O3+P3+Q3+R3+S3 -> 42787.86 | U3: =+T3*100/T12 -> 36.188601 | V3: 1 | W3: ที.ซีฟาร์มาฯ | X3: 42787.86 | Y3: 0 | Z3: =+X3+Y3 -> 42787.86 | AB3: 1 | AC3: สยามอุตสาหกรรมวัสดุทนไฟ | AD3: 4909.7008 | AE3: 23800 | AF3: 0 | AG3: =+AD3+AF3 -> 4909.7008
A4: 2 | B4: ที.ซีฟาร์มาฯ | C4: 90395.7 | D4: 42787.86 | E4: 0 | F4: 0 | G4: 0 | H4: =+C4+D4+E4+F4+G4 -> 133183.56 | I4: BWP | J4: =+H4*100/H52 -> 20.385068 | L4: 2 | M4: กรีนสปอต | N4: 1436.5 | O4: 40115.65 | P4: 0 | Q4: 0 | R4: 0 | S4: 0 | T4: =N4+O4+P4+Q4+R4+S4 -> 41552.15 | U4: =+T4*100/T12 -> 35.143477 | V4: 2 | W4: กรีนสปอต | X4: 35209.47 | Y4: 6342.68 | Z4: =+X4+Y4 -> 41552.15 | AB4: 2 | AC4: ปูนซิเมนต์ไทย(ท่าหลวง)(โรงงานเขาวง) | AD4: 2829 | AE4: 15000 | AF4: 0 | AG4: =+AD4+AF4 -> 2829
A5: 3 | B5: หาดทิพย์ | C5: 131868.14 | D5: 0 | E5: 0 | F5: 0 | G5: 0 | H5: =+C5+D5+E5+F5+G5 -> 131868.14 | J5: =+H5*100/H52 -> 20.18373 | L5: 3 | M5: ฟรีสแลนด์คัมพิน่า | N5: 0 | O5: 14388.91 | P5: 0 | Q5: 0 | R5: 0 | S5: 0 | T5: =N5+O5+P5+Q5+R5+S5 -> 14388.91 | U5: =+T5*100/T12 -> 12.169679 | V5: 3 | W5: ฟรีสแลนด์คัมพิน่า | X5: 14388.91 | Y5: 0 | Z5: =+X5+Y5 -> 14388.91 | AB5: 3 | AC5: เอ็น พลัส ชัพพลาย | AD5: 2216 | AE5: 2000 | AF5: 0 | AG5: =+AD5+AF5 -> 2216
A6: 4 | B6: โอสถสภา | C6: 55416.7 | D6: 0 | E6: 0 | F6: 0 | G6: 0 | H6: =+C6+D6+E6+F6+G6 -> 55416.7 | J6: =+H6*100/H52 -> 8.4820769 | L6: 4 | M6: โตโยไซกัน | N6: 0 | O6: 9588.75 | P6: 296.5 | Q6: 0 | R6: 0 | S6: 0 | T6: =N6+O6+P6+Q6+R6+S6 -> 9885.25 | U6: =+T6*100/T12 -> 8.3606277 | V6: 4 | W6: โตโยไซกัน | X6: 9885.25 | Y6: 0 | Z6: =+X6+Y6 -> 9885.25 | AB6: 4 | AC6: สยามกลาสอยุธยา | AD6: 251.15 | AE6: 500 | AF6: 0 | AG6: =+AD6+AF6 -> 251.15
A7: 5 | B7: กรีนสปอต | C7: 4137.42 | D7: 41552.15 | E7: 0 | F7: 1989 | G7: 0 | H7: =+C7+D7+E7+F7+G7 -> 47678.57 | I7: BWP/WT | J7: =+H7*100/H52 -> 7.2976791 | L7: 5 | M7: สหกรณ์โคนมหนองโพ | N7: 0 | O7: 1074.3 | P7: 0 | Q7: 0 | R7: 0 | S7: 0 | T7: =N7+O7+P7+Q7+R7+S7 -> 1074.3 | U7: =+T7*100/T12 -> 0.90860851 | V7: 5 | W7: สหกรณ์โคนมหนองโพ | X7: 1074.3 | Y7: 0 | Z7: =+X7+Y7 -> 1074.3 | AB7: 5 | AC7: เอสซีจี เซรามิกส์ | AD7: 204.288 | AE7: 560 | AF7: 0 | AG7: =+AD7+AF7 -> 204.288
A8: 6 | B8: ฟรีสแลนด์คัมพิน่า | C8: 0 | D8: 14388.91 | E8: 0 | F8: 0 | G8: 0 | H8: =+C8+D8+E8+F8+G8 -> 14388.91 | I8: BWP | J8: =+H8*100/H52 -> 2.2023657 | L8: 6 | M8: แอดวานซ์ โนเลดจ์ เซอร์วิสเซส | N8: 0 | O8: 4962.37 | P8: 0 | Q8: 0 | R8: 0 | S8: 0 | T8: =N8+O8+P8+Q8+R8+S8 -> 4962.37 | U8: =+T8*100/T12 -> 4.1970135 | V8: 6 | W8: แอดวานซ์ โนเลดจ์ เซอร์วิสเซส | X8: 4962.37 | Y8: 0 | Z8: =+X8+Y8 -> 4962.37 | AB8: 6 | AC8: คาเนมัทสุ สเปเชียล สลีล เซอร์วิส | AD8: 170.5 | AE8: 500 | AF8: 0 | AG8: =+AD8+AF8 -> 170.5
A9: 7 | B9: โตโยไซกัน | C9: 3422 | D9: 9885.25 | E9: 0 | F9: 0 | G9: 0 | H9: =+C9+D9+E9+F9+G9 -> 13307.25 | I9: BWP | J9: =+H9*100/H52 -> 2.0368069 | L9: 7 | M9: สยามไฟเบอร์ซีเมนต์กรุ๊ป | N9: 0 | O9: 2104.25 | P9: 0 | Q9: 0 | R9: 0 | S9: 0 | T9: =N9+O9+P9+Q9+R9+S9 -> 2104.25 | U9: =+T9*100/T12 -> 1.7797072 | V9: 7 | W9: สยามไฟเบอร์ซีเมนต์กรุ๊ป | X9: 2104.25 | Y9: 0 | Z9: =+X9+Y9 -> 2104.25 | AC9: ผลรวม | AD9: =SUM(AD3:AD8) -> 10580.639 | AE9: =SUM(AE3:AE8) -> 42360 | AF9: =SUM(AF3:AF8) -> 0 | AG9: =SUM(AG3:AG8) -> 10580.639
A10: 8 | B10: เสริมสุข | C10: 8923.4 | D10: 0 | E10: 0 | F10: 0 | G10: 0 | H10: =+C10+D10+E10+F10+G10 -> 8923.4 | J10: =+H10*100/H52 -> 1.3658151 | L10: 8 | M10: ยูนิ-เพรสซิเดนท์ | N10: 0 | O10: 1025.65 | P10: 0 | Q10: 0 | R10: 0 | S10: 0 | T10: =N10+O10+P10+Q10+R10+S10 -> 1025.65 | U10: =+T10*100/T12 -> 0.8674619 | V10: 8 | W10: ยูนิ-เพรสซิเดนท์ | X10: 1025.65 | Y10: 0 | Z10: =+X10+Y10 -> 1025.65
A11: 9 | B11: เซเว่นสตาร์ | C11: 6181.45 | D11: 0 | E11: 0 | F11: 0 | G11: 0 | H11: =+C11+D11+E11+F11+G11 -> 6181.45 | J11: =+H11*100/H52 -> 0.94613238 | L11: 10 | M11: เจ.เอส.อุตสาหกรรมพลาสติก | N11: 0 | O11: 455 | P11: 0 | Q11: 0 | R11: 0 | S11: 0 | T11: =N11+O11+P11+Q11+R11+S11 -> 455 | U11: =+T11*100/T12 -> 0.38482442 | V11: 10 | W11: เจ.เอส.อุตสาหกรรมพลาสติก | X11: 455 | Y11: 0 | Z11: =+X11+Y11 -> 455
A12: 10 | B12: สหกรณ์โคนมหนองโพ | C12: 4925.1 | D12: 1074.3 | E12: 0 | F12: 0 | G12: 0 | H12: =+C12+D12+E12+F12+G12 -> 5999.4 | I12: BWP | J12: =+H12*100/H52 -> 0.91826781 | M12: ผลรวม | N12: =SUM(N3:N11) -> 1436.5 | O12: =SUM(O3:O11) -> 112027.54 | P12: =SUM(P3:P11) -> 296.5 | Q12: =SUM(Q3:Q11) -> 0 | R12: =SUM(R3:R11) -> 4475.2 | S12: =SUM(S3:S11) -> 0 | T12: =SUM(T3:T11) -> 118235.74 | W12: ผลรวม | X12: =SUM(X3:X11) -> 111893.06 | Y12: =SUM(Y3:Y11) -> 6342.68 | Z12: =SUM(Z3:Z11) -> 118235.74
A13: 11 | B13: เอ็มเอ็มพี คอร์ปอเรชั่น | C13: 5907.55 | D13: 0 | E13: 0 | F13: 0 | G13: 0 | H13: =+C13+D13+E13+F13+G13 -> 5907.55
A14: 12 | B14: กรีนสวิลล์ | C14: 5684.15 | D14: 0 | E14: 0 | F14: 0 | G14: 0 | H14: =+C14+D14+E14+F14+G14 -> 5684.15 | N14: =+N12*100/T12 -> 1.2149457 | O14: =+O12*100/T12 -> 94.749303 | P14: =+P12*100/T12 -> 0.2507702 | Q14: =+Q12*100/T12 -> 0 | R14: =+R12*100/T12 -> 3.7849808 | S14: =+S12*100/T12 -> 0 | X14: =+X12*100/Z12 -> 94.635565 | Y14: =+Y12*100/Z12 -> 5.3644355
A15: 13 | B15: แอดวานซ์ โนเลดจ์ เซอร์วิสเซส | C15: 0 | D15: 4962.37 | E15: 0 | F15: 0 | G15: 0 | H15: =+C15+D15+E15+F15+G15 -> 4962.37 | I15: BWP
A16: 14 | B16: สยามอุตสาหกรรมวัสดุทนไฟ | C16: 0 | D16: 0 | E16: 4909.7008 | F16: 0 | G16: 0 | H16: =+C16+D16+E16+F16+G16 -> 4909.7008
A17: 15 | B17: ทิพย์นที (2005) | C17: 4701.8 | D17: 0 | E17: 0 | F17: 0 | G17: 0 | H17: =+C17+D17+E17+F17+G17 -> 4701.8
A18: 16 | B18: เพชรพาณิชย์ เบฟเวอเรจ | C18: 4118.5 | D18: 0 | E18: 0 | F18: 0 | G18: 0 | H18: =+C18+D18+E18+F18+G18 -> 4118.5
A19: 17 | B19: ฐิติรัตน์ | C19: 3987.95 | D19: 0 | E19: 0 | F19: 0 | G19: 0 | H19: =+C19+D19+E19+F19+G19 -> 3987.95
A20: 18 | B20: เถิงธงพานิชย์ | C20: 3488.05 | D20: 0 | E20: 0 | F20: 0 | G20: 0 | H20: =+C20+D20+E20+F20+G20 -> 3488.05
A21: 19 | B21: ฐิติภัณฑ์ อินเตอร์พลัส | C21: 3034.65 | D21: 0 | E21: 0 | F21: 124.2 | G21: 0 | H21: =+C21+D21+E21+F21+G21 -> 3158.85
A22: 20 | B22: ปูนซิเมนต์ไทย(ท่าหลวง)(โรงงานเขาวง) | C22: 0 | D22: 0 | E22: 2829 | F22: 0 | G22: 0 | H22: =+C22+D22+E22+F22+G22 -> 2829
A23: 21 | B23: เอ็น พลัส ชัพพลาย | C23: 0 | D23: 0 | E23: 2216 | F23: 0 | G23: 0 | H23: =+C23+D23+E23+F23+G23 -> 2216
A24: 22 | B24: ขายยาเพ็ญภาค | C24: 2161.6 | D24: 0 | E24: 0 | F24: 0 | G24: 0 | H24: =+C24+D24+E24+F24+G24 -> 2161.6
A25: 23 | B25: สยามไฟเบอร์ซีเมนต์กรุ๊ป | C25: 0 | D25: 2104.25 | E25: 0 | F25: 0 | G25: 0 | H25: =+C25+D25+E25+F25+G25 -> 2104.25 | I25: BWP
A26: 24 | B26: จอมธนา | C26: 1983.75 | D26: 0 | E26: 0 | F26: 0 | G26: 0 | H26: =+C26+D26+E26+F26+G26 -> 1983.75
A27: 25 | B27: สุรใจฟู้ดส์อินดัสทรี | C27: 1971.35 | D27: 0 | E27: 0 | F27: 0 | G27: 0 | H27: =+C27+D27+E27+F27+G27 -> 1971.35
A28: 26 | B28: อินคาวอเตอร์ | C28: 1915.75 | D28: 0 | E28: 0 | F28: 0 | G28: 0 | H28: =+C28+D28+E28+F28+G28 -> 1915.75
